Workbook
Name episodeCode: #REF!
Name excemail: #REF!

Sheet Sheet1
A1: product | B1: parent_episode | C1: EpisodeId | D1: episode_code | E1: StepId | F1: step_name | G1: Definition Agreed | H1: Volumes From Chill | I1: Priority
A2: Motor | B2: ACQUISITION_JOURNEY | C2: 1 | D2: MOTOR_QUOTE_JOURNEY | E2: 1 | F2: Quote initiated | I2: 1
A3: Motor | B3: ACQUISITION_JOURNEY | C3: 1 | D3: MOTOR_QUOTE_JOURNEY | E3: 2 | F3: Site landing page viewed
A4: Motor | B4: ACQUISITION_JOURNEY | C4: 1 | D4: MOTOR_QUOTE_JOURNEY | E4: 3 | F4: Quote progressed | G4: Not Sure | I4: 1
A5: Motor | B5: ACQUISITION_JOURNEY | C5: 1 | D5: MOTOR_QUOTE_JOURNEY | E5: 4 | F5: Inbound sales contact
A6: Motor | B6: ACQUISITION_JOURNEY | C6: 1 | D6: MOTOR_QUOTE_JOURNEY | E6: 5 | F6: Outbound sales callback
A7: Motor | B7: ACQUISITION_JOURNEY | C7: 1 | D7: MOTOR_QUOTE_JOURNEY | E7: 6 | F7: Web assist engagement | I7: 1
A8: Motor | B8: ACQUISITION_JOURNEY | C8: 1 | D8: MOTOR_QUOTE_JOURNEY | E8: 7 | F8: Quote abandoned
A9: Motor | B9: ACQUISITION_JOURNEY | C9: 1 | D9: MOTOR_QUOTE_JOURNEY | E9: 8 | F9: Service Retrieve | G9: Not Sure | I9: 1
A10: Motor | B10: ACQUISITION_JOURNEY | C10: 1 | D10: MOTOR_QUOTE_JOURNEY | E10: 9 | F10: XP retrieve journey triggered
A11: Motor | B11: ACQUISITION_JOURNEY | C11: 1 | D11: MOTOR_QUOTE_JOURNEY | E11: 10 | F11: Payment attempted (with friction)
A12: Motor | B12: ACQUISITION_JOURNEY | C12: 1 | D12: MOTOR_QUOTE_JOURNEY | E12: 11 | F12: Payment successful | I12: 1
A13: Motor | B13: ACQUISITION_JOURNEY | C13: 1 | D13: MOTOR_QUOTE_JOURNEY | E13: 12 | F13: Post-sale document pack sent (TOB / Proposal / Quote Breakdown)
A14: Motor | B14: ACQUISITION_JOURNEY | C14: 2 | D14: MOTOR_ACQUISITION_CALL_CENTRE | E14: 1 | F14: Inbound sales contact (no MFQ match)
A15: Motor | B15: ACQUISITION_JOURNEY | C15: 2 | D15: MOTOR_ACQUISITION_CALL_CENTRE | E15: 2 | F15: Agent quotes in Genesis | I15: 1
A16: Motor | B16: ACQUISITION_JOURNEY | C16: 2 | D16: MOTOR_ACQUISITION_CALL_CENTRE | E16: 3 | F16: Payment successful | I16: 1
A17: Motor | B17: ACQUISITION_JOURNEY | C17: 2 | D17: MOTOR_ACQUISITION_CALL_CENTRE | E17: 4 | F17: Not proceeded with
A18: Motor | B18: ACQUISITION_JOURNEY | C18: 3 | D18: MOTOR_QUOTE_RETRIEVE | E18: 1 | F18: Quote retrieved / iterated | I18: 1
A19: Motor | B19: ACQUISITION_JOURNEY | C19: 3 | D19: MOTOR_QUOTE_RETRIEVE | E19: 2 | F19: Purchase
A20: Motor | B20: ACQUISITION_JOURNEY | C20: 3 | D20: MOTOR_QUOTE_RETRIEVE | E20: 3 | F20: Abandoned / expired
A21: Motor | B21: ACQUISITION_JOURNEY | C21: 4 | D21: MOTOR_DOCUMENT_INTAKE | E21: 1 | F21: Document request issued | I21: 1
A22: Motor | B22: ACQUISITION_JOURNEY | C22: 4 | D22: MOTOR_DOCUMENT_INTAKE | E22: 2 | F22: Customer submits documents
A23: Motor | B23: ACQUISITION_JOURNEY | C23: 4 | D23: MOTOR_DOCUMENT_INTAKE | E23: 3 | F23: Documents validated
A24: Motor | B24: ACQUISITION_JOURNEY | C24: 4 | D24: MOTOR_DOCUMENT_INTAKE | E24: 4 | F24: Chase — first reminder
A25: Motor | B25: ACQUISITION_JOURNEY | C25: 4 | D25: MOTOR_DOCUMENT_INTAKE | E25: 5 | F25: Chase — escalation
A26: Motor | B26: ACQUISITION_JOURNEY | C26: 4 | D26: MOTOR_DOCUMENT_INTAKE | E26: 6 | F26: Documents received & validated | I26: 1
A27: Motor | B27: ACQUISITION_JOURNEY | C27: 4 | D27: MOTOR_DOCUMENT_INTAKE | E27: 7 | F27: Cancellation — non-receipt | I27: 1
A28: Motor | B28: ACQUISITION_JOURNEY | C28: 5 | D28: MOTOR_PAYMENT_SETUP_LOAN | E28: 1 | F28: Loan initiated with finance provider | I28: 1
A29: Motor | B29: ACQUISITION_JOURNEY | C29: 5 | D29: MOTOR_PAYMENT_SETUP_LOAN | E29: 2 | F29: Finance application link sent (SMS + email from finance provider)
A30: Motor | B30: ACQUISITION_JOURNEY | C30: 5 | D30: MOTOR_PAYMENT_SETUP_LOAN | E30: 3 | F30: Customer completes application / DD setup (provider portal)
A31: Motor | B31: ACQUISITION_JOURNEY | C31: 5 | D31: MOTOR_PAYMENT_SETUP_LOAN | E31: 4 | F31: Chase — inconsistency resolution
A32: Motor | B32: ACQUISITION_JOURNEY | C32: 5 | D32: MOTOR_PAYMENT_SETUP_LOAN | E32: 5 | F32: Payment confirmed — loan path
A33: Motor | B33: ACQUISITION_JOURNEY | C33: 5 | D33: MOTOR_PAYMENT_SETUP_LOAN | E33: 6 | F33: Switched to pay-in-full
A34: Motor | B34: ACQUISITION_JOURNEY | C34: 5 | D34: MOTOR_PAYMENT_SETUP_LOAN | E34: 7 | F34: Cancellation — loan setup failed | I34: 1
A35: Motor | B35: ACQUISITION_JOURNEY | C35: 6 | D35: MOTOR_PAYMENT_SETUP_LOAN_PC | E35: 1 | F35: Loan initiated — integrated in the quote stage | I35: 1
A36: Motor | B36: ACQUISITION_JOURNEY | C36: 6 | D36: MOTOR_PAYMENT_SETUP_LOAN_PC | E36: 2 | F36: Finance application link sent (SMS + email from Premium Credit)
A37: Motor | B37: ACQUISITION_JOURNEY | C37: 6 | D37: MOTOR_PAYMENT_SETUP_LOAN_PC | E37: 3 | F37: Customer completes self-service application (docs uploaded in PC app)
A38: Motor | B38: ACQUISITION_JOURNEY | C38: 6 | D38: MOTOR_PAYMENT_SETUP_LOAN_PC | E38: 4 | F38: Document chase (provider chase + Chill chase)
A39: Motor | B39: ACQUISITION_JOURNEY | C39: 6 | D39: MOTOR_PAYMENT_SETUP_LOAN_PC | E39: 5 | F39: Payment confirmed — loan path
A40: Motor | B40: ACQUISITION_JOURNEY | C40: 6 | D40: MOTOR_PAYMENT_SETUP_LOAN_PC | E40: 6 | F40: Switched to pay-in-full
...

Sheet Summary
B2: Product | C2: Journey | D2: Priority Data Points | M2: Other Data Points | N2: Total Data Points | O2: Total Fabric Coverage | P2: Total Fabric Not Provided | Q2: Total Fabric Coverage % | R2: Is Data / Logic Available / accessible?
D3: Priority Total | E3: Reconciled | F3: Reconciled within acceptable variance | G3: Under Investigation | H3: No report data supplied | I3: No data Available | J3: Available in IGP (Fabric) | K3: % Coverage Missing in Fabric | L3: % Coverage in IGP (Fabric) | R3: Yes | S3: No | T3: Not a Data Point
B5: Motor | C5: Acquisition | D5: =COUNTIFS('Reconciliation Request'!$A$2:$A$755,Summary!$B5,'Reconciliation Request'!$B$2:$B$755,Summary!$C5,'Reconciliation Request'!$F$2:$F$755,"=1") -> 11 | E5: =COUNTIFS('Reconciliation Request'!$A$2:$A$755,Summary!$B5,'Reconciliation Request'!$B$2:$B$755,Summary!$C5,'Reconciliation Request'!$J$2:$J$755,Summary!E$3,'Reconciliation Request'!$F$2:$F$755,"=1") -> 3 | F5: =COUNTIFS('Reconciliation Request'!$A$2:$A$755,Summary!$B5,'Reconciliation Request'!$B$2:$B$755,Summary!$C5,'Reconciliation Request'!$J$2:$J$755,Summary!F$3,'Reconciliation Request'!$F$2:$F$755,"=1") -> 3 | G5: =COUNTIFS('Reconciliation Request'!$A$2:$A$755,Summary!$B5,'Reconciliation Request'!$B$2:$B$755,Summary!$C5,'Reconciliation Request'!$J$2:$J$755,Summary!G$3,'Reconciliation Request'!$F$2:$F$755,"=1") -> 0 | H5: =COUNTIFS('Reconciliation Request'!$A$2:$A$755,Summary!$B5,'Reconciliation Request'!$B$2:$B$755,Summary!$C5,'Reconciliation Request'!$J$2:$J$755,Summary!H$3,'Reconciliation Request'!$F$2:$F$755,"=1") -> 2 | I5: 0 | J5: =COUNTIFS('Reconciliation Request'!$A$2:$A$755,Summary!$B5,'Reconciliation Request'!$B$2:$B$755,Summary!$C5,'Reconciliation Request'!$H$2:$H$755,">0",'Reconciliation Request'!$F$2:$F$755,"=1") -> 11 | K5: =I5/D5 -> 0 | L5: =J5/D5 -> 1 | M5: =COUNTIFS('Reconciliation Request'!$A$2:$A$755,Summary!$B5,'Reconciliation Request'!$B$2:$B$755,Summary!$C5,'Reconciliation Request'!$F$2:$F$755,"<>1") -> 59 | N5: =M5+D5 -> 70 | O5: =COUNTIFS('Reconciliation Request'!$A$2:$A$755,Summary!$B5,'Reconciliation Request'!$B$2:$B$755,Summary!$C5,'Reconciliation Request'!$H$2:$H$755,">0") -> 40 | P5: =N5-O5 -> 30 | Q5: =O5/N5 -> 0.57142857 | R5: =COUNTIFS('Reconciliation Request'!$A$2:$A$755,Summary!$B5,'Reconciliation Request'!$B$2:$B$755,Summary!$C5,'Reconciliation Request'!$K$2:$K$755,R$3) -> 42 | S5: =COUNTIFS('Reconciliation Request'!$A$2:$A$755,Summary!$B5,'Reconciliation Request'!$B$2:$B$755,Summary!$C5,'Reconciliation Request'!$K$2:$K$755,S$3) -> 28 | T5: =COUNTIFS('Reconciliation Request'!$A$2:$A$755,Summary!$B5,'Reconciliation Request'!$B$2:$B$755,Summary!$C5,'Reconciliation Request'!$K$2:$K$755,T$3) -> 0
B6: Motor | C6: Renewal | D6: =COUNTIFS('Reconciliation Request'!$A$2:$A$755,Summary!$B6,'Reconciliation Request'!$B$2:$B$755,Summary!$C6,'Reconciliation Request'!$F$2:$F$755,"=1") -> 11 | E6: =COUNTIFS('Reconciliation Request'!$A$2:$A$755,Summary!$B6,'Reconciliation Request'!$B$2:$B$755,Summary!$C6,'Reconciliation Request'!$J$2:$J$755,Summary!E$3,'Reconciliation Request'!$F$2:$F$755,"=1") -> 0 | F6: =COUNTIFS('Reconciliation Request'!$A$2:$A$755,Summary!$B6,'Reconciliation Request'!$B$2:$B$755,Summary!$C6,'Reconciliation Request'!$J$2:$J$755,Summary!F$3,'Reconciliation Request'!$F$2:$F$755,"=1") -> 5 | G6: =COUNTIFS('Reconciliation Request'!$A$2:$A$755,Summary!$B6,'Reconciliation Request'!$B$2:$B$755,Summary!$C6,'Reconciliation Request'!$J$2:$J$755,Summary!G$3,'Reconciliation Request'!$F$2:$F$755,"=1") -> 1 | H6: =COUNTIFS('Reconciliation Request'!$A$2:$A$755,Summary!$B6,'Reconciliation Request'!$B$2:$B$755,Summary!$C6,'Reconciliation Request'!$J$2:$J$755,Summary!H$3,'Reconciliation Request'!$F$2:$F$755,"=1") -> 4 | I6: 1 | J6: 10 | K6: =I6/D6 -> 0.090909091 | L6: =J6/D6 -> 0.90909091 | M6: =COUNTIFS('Reconciliation Request'!$A$2:$A$755,Summary!$B6,'Reconciliation Request'!$B$2:$B$755,Summary!$C6,'Reconciliation Request'!$F$2:$F$755,"<>1") -> 72 | N6: =M6+D6 -> 83 | O6: =COUNTIFS('Reconciliation Request'!$A$2:$A$755,Summary!$B6,'Reconciliation Request'!$B$2:$B$755,Summary!$C6,'Reconciliation Request'!$H$2:$H$755,">0") -> 54 | P6: =N6-O6 -> 29 | Q6: =O6/N6 -> 0.65060241 | R6: =COUNTIFS('Reconciliation Request'!$A$2:$A$755,Summary!$B6,'Reconciliation Request'!$B$2:$B$755,Summary!$C6,'Reconciliation Request'!$K$2:$K$755,R$3) -> 57 | S6: =COUNTIFS('Reconciliation Request'!$A$2:$A$755,Summary!$B6,'Reconciliation Request'!$B$2:$B$755,Summary!$C6,'Reconciliation Request'!$K$2:$K$755,S$3) -> 14 | T6: =COUNTIFS('Reconciliation Request'!$A$2:$A$755,Summary!$B6,'Reconciliation Request'!$B$2:$B$755,Summary!$C6,'Reconciliation Request'!$K$2:$K$755,T$3) -> 9
B7: Home | C7: Acquisition | D7: 11 | E7: =COUNTIFS('Reconciliation Request'!$A$2:$A$755,Summary!$B7,'Reconciliation Request'!$B$2:$B$755,Summary!$C7,'Reconciliation Request'!$J$2:$J$755,Summary!E$3,'Reconciliation Request'!$F$2:$F$755,"=1") -> 3 | F7: =COUNTIFS('Reconciliation Request'!$A$2:$A$755,Summary!$B7,'Reconciliation Request'!$B$2:$B$755,Summary!$C7,'Reconciliation Request'!$J$2:$J$755,Summary!F$3,'Reconciliation Request'!$F$2:$F$755,"=1") -> 2 | G7: =COUNTIFS('Reconciliation Request'!$A$2:$A$755,Summary!$B7,'Reconciliation Request'!$B$2:$B$755,Summary!$C7,'Reconciliation Request'!$J$2:$J$755,Summary!G$3,'Reconciliation Request'!$F$2:$F$755,"=1") -> 0 | H7: =COUNTIFS('Reconciliation Request'!$A$2:$A$755,Summary!$B7,'Reconciliation Request'!$B$2:$B$755,Summary!$C7,'Reconciliation Request'!$J$2:$J$755,Summary!H$3,'Reconciliation Request'!$F$2:$F$755,"=1") -> 7 | I7: 0 | J7: 11 | K7: =I7/D7 -> 0 | L7: =J7/D7 -> 1 | M7: =COUNTIFS('Reconciliation Request'!$A$2:$A$755,Summary!$B7,'Reconciliation Request'!$B$2:$B$755,Summary!$C7,'Reconciliation Request'!$F$2:$F$755,"<>1") -> 44 | N7: =M7+D7 -> 55 | O7: =COUNTIFS('Reconciliation Request'!$A$2:$A$755,Summary!$B7,'Reconciliation Request'!$B$2:$B$755,Summary!$C7,'Reconciliation Request'!$H$2:$H$755,">0") -> 34 | P7: =N7-O7 -> 21 | Q7: =O7/N7 -> 0.61818182 | R7: =COUNTIFS('Reconciliation Request'!$A$2:$A$755,Summary!$B7,'Reconciliation Request'!$B$2:$B$755,Summary!$C7,'Reconciliation Request'!$K$2:$K$755,R$3) -> 38 | S7: =COUNTIFS('Reconciliation Request'!$A$2:$A$755,Summary!$B7,'Reconciliation Request'!$B$2:$B$755,Summary!$C7,'Reconciliation Request'!$K$2:$K$755,S$3) -> 17 | T7: =COUNTIFS('Reconciliation Request'!$A$2:$A$755,Summary!$B7,'Reconciliation Request'!$B$2:$B$755,Summary!$C7,'Reconciliation Request'!$K$2:$K$755,T$3) -> 1
B8: Home | C8: Renewal | D8: =COUNTIFS('Reconciliation Request'!$A$2:$A$755,Summary!$B8,'Reconciliation Request'!$B$2:$B$755,Summary!$C8,'Reconciliation Request'!$F$2:$F$755,"=1") -> 7 | E8: =COUNTIFS('Reconciliation Request'!$A$2:$A$755,Summary!$B8,'Reconciliation Request'!$B$2:$B$755,Summary!$C8,'Reconciliation Request'!$J$2:$J$755,Summary!E$3,'Reconciliation Request'!$F$2:$F$755,"=1") -> 1 | F8: =COUNTIFS('Reconciliation Request'!$A$2:$A$755,Summary!$B8,'Reconciliation Request'!$B$2:$B$755,Summary!$C8,'Reconciliation Request'!$J$2:$J$755,Summary!F$3,'Reconciliation Request'!$F$2:$F$755,"=1") -> 4 | G8: =COUNTIFS('Reconciliation Request'!$A$2:$A$755,Summary!$B8,'Reconciliation Request'!$B$2:$B$755,Summary!$C8,'Reconciliation Request'!$J$2:$J$755,Summary!G$3,'Reconciliation Request'!$F$2:$F$755,"=1") -> 0 | H8: =COUNTIFS('Reconciliation Request'!$A$2:$A$755,Summary!$B8,'Reconciliation Request'!$B$2:$B$755,Summary!$C8,'Reconciliation Request'!$J$2:$J$755,Summary!H$3,'Reconciliation Request'!$F$2:$F$755,"=1") -> 2 | I8: 1 | J8: =COUNTIFS('Reconciliation Request'!$A$2:$A$755,Summary!$B8,'Reconciliation Request'!$B$2:$B$755,Summary!$C8,'Reconciliation Request'!$H$2:$H$755,">0",'Reconciliation Request'!$F$2:$F$755,"=1") -> 6 | K8: =I8/D8 -> 0.14285714 | L8: =J8/D8 -> 0.85714286 | M8: =COUNTIFS('Reconciliation Request'!$A$2:$A$755,Summary!$B8,'Reconciliation Request'!$B$2:$B$755,Summary!$C8,'Reconciliation Request'!$F$2:$F$755,"<>1") -> 61 | N8: =M8+D8 -> 68 | O8: =COUNTIFS('Reconciliation Request'!$A$2:$A$755,Summary!$B8,'Reconciliation Request'!$B$2:$B$755,Summary!$C8,'Reconciliation Request'!$H$2:$H$755,">0") -> 49 | P8: =N8-O8 -> 19 | Q8: =O8/N8 -> 0.72058824 | R8: =COUNTIFS('Reconciliation Request'!$A$2:$A$755,Summary!$B8,'Reconciliation Request'!$B$2:$B$755,Summary!$C8,'Reconciliation Request'!$K$2:$K$755,R$3) -> 50 | S8: =COUNTIFS('Reconciliation Request'!$A$2:$A$755,Summary!$B8,'Reconciliation Request'!$B$2:$B$755,Summary!$C8,'Reconciliation Request'!$K$2:$K$755,S$3) -> 14 | T8: =COUNTIFS('Reconciliation Request'!$A$2:$A$755,Summary!$B8,'Reconciliation Request'!$B$2:$B$755,Summary!$C8,'Reconciliation Request'!$K$2:$K$755,T$3) -> 4
B9: Van | C9: Acquisition | D9: =COUNTIFS('Reconciliation Request'!$A$2:$A$755,Summary!$B9,'Reconciliation Request'!$B$2:$B$755,Summary!$C9,'Reconciliation Request'!$F$2:$F$755,"=1") -> 7 | E9: =COUNTIFS('Reconciliation Request'!$A$2:$A$755,Summary!$B9,'Reconciliation Request'!$B$2:$B$755,Summary!$C9,'Reconciliation Request'!$J$2:$J$755,Summary!E$3,'Reconciliation Request'!$F$2:$F$755,"=1") -> 1 | F9: =COUNTIFS('Reconciliation Request'!$A$2:$A$755,Summary!$B9,'Reconciliation Request'!$B$2:$B$755,Summary!$C9,'Reconciliation Request'!$J$2:$J$755,Summary!F$3,'Reconciliation Request'!$F$2:$F$755,"=1") -> 2 | G9: =COUNTIFS('Reconciliation Request'!$A$2:$A$755,Summary!$B9,'Reconciliation Request'!$B$2:$B$755,Summary!$C9,'Reconciliation Request'!$J$2:$J$755,Summary!G$3,'Reconciliation Request'!$F$2:$F$755,"=1") -> 0 | H9: =COUNTIFS('Reconciliation Request'!$A$2:$A$755,Summary!$B9,'Reconciliation Request'!$B$2:$B$755,Summary!$C9,'Reconciliation Request'!$J$2:$J$755,Summary!H$3,'Reconciliation Request'!$F$2:$F$755,"=1") -> 4 | I9: 0 | J9: =COUNTIFS('Reconciliation Request'!$A$2:$A$755,Summary!$B9,'Reconciliation Request'!$B$2:$B$755,Summary!$C9,'Reconciliation Request'!$H$2:$H$755,">0",'Reconciliation Request'!$F$2:$F$755,"=1") -> 7 | K9: =I9/D9 -> 0 | L9: =J9/D9 -> 1 | M9: =COUNTIFS('Reconciliation Request'!$A$2:$A$755,Summary!$B9,'Reconciliation Request'!$B$2:$B$755,Summary!$C9,'Reconciliation Request'!$F$2:$F$755,"<>1") -> 30 | N9: =M9+D9 -> 37 | O9: =COUNTIFS('Reconciliation Request'!$A$2:$A$755,Summary!$B9,'Reconciliation Request'!$B$2:$B$755,Summary!$C9,'Reconciliation Request'!$H$2:$H$755,">0") -> 22 | P9: =N9-O9 -> 15 | Q9: =O9/N9 -> 0.59459459 | R9: =COUNTIFS('Reconciliation Request'!$A$2:$A$755,Summary!$B9,'Reconciliation Request'!$B$2:$B$755,Summary!$C9,'Reconciliation Request'!$K$2:$K$755,R$3) -> 23 | S9: =COUNTIFS('Reconciliation Request'!$A$2:$A$755,Summary!$B9,'Reconciliation Request'!$B$2:$B$755,Summary!$C9,'Reconciliation Request'!$K$2:$K$755,S$3) -> 11 | T9: =COUNTIFS('Reconciliation Request'!$A$2:$A$755,Summary!$B9,'Reconciliation Request'!$B$2:$B$755,Summary!$C9,'Reconciliation Request'!$K$2:$K$755,T$3) -> 3
B10: Van | C10: Renewal | D10: =COUNTIFS('Reconciliation Request'!$A$2:$A$755,Summary!$B10,'Reconciliation Request'!$B$2:$B$755,Summary!$C10,'Reconciliation Request'!$F$2:$F$755,"=1") -> 8 | E10: =COUNTIFS('Reconciliation Request'!$A$2:$A$755,Summary!$B10,'Reconciliation Request'!$B$2:$B$755,Summary!$C10,'Reconciliation Request'!$J$2:$J$755,Summary!E$3,'Reconciliation Request'!$F$2:$F$755,"=1") -> 1 | F10: =COUNTIFS('Reconciliation Request'!$A$2:$A$755,Summary!$B10,'Reconciliation Request'!$B$2:$B$755,Summary!$C10,'Reconciliation Request'!$J$2:$J$755,Summary!F$3,'Reconciliation Request'!$F$2:$F$755,"=1") -> 3 | G10: =COUNTIFS('Reconciliation Request'!$A$2:$A$755,Summary!$B10,'Reconciliation Request'!$B$2:$B$755,Summary!$C10,'Reconciliation Request'!$J$2:$J$755,Summary!G$3,'Reconciliation Request'!$F$2:$F$755,"=1") -> 0 | H10: =COUNTIFS('Reconciliation Request'!$A$2:$A$755,Summary!$B10,'Reconciliation Request'!$B$2:$B$755,Summary!$C10,'Reconciliation Request'!$J$2:$J$755,Summary!H$3,'Reconciliation Request'!$F$2:$F$755,"=1") -> 4 | I10: 1 | J10: =COUNTIFS('Reconciliation Request'!$A$2:$A$755,Summary!$B10,'Reconciliation Request'!$B$2:$B$755,Summary!$C10,'Reconciliation Request'!$H$2:$H$755,">0",'Reconciliation Request'!$F$2:$F$755,"=1") -> 7 | K10: =I10/D10 -> 0.125 | L10: =J10/D10 -> 0.875 | M10: =COUNTIFS('Reconciliation Request'!$A$2:$A$755,Summary!$B10,'Reconciliation Request'!$B$2:$B$755,Summary!$C10,'Reconciliation Request'!$F$2:$F$755,"<>1") -> 49 | N10: =M10+D10 -> 57 | O10: =COUNTIFS('Reconciliation Request'!$A$2:$A$755,Summary!$B10,'Reconciliation Request'!$B$2:$B$755,Summary!$C10,'Reconciliation Request'!$H$2:$H$755,">0") -> 25 | P10: =N10-O10 -> 32 | Q10: =O10/N10 -> 0.43859649 | R10: =COUNTIFS('Reconciliation Request'!$A$2:$A$755,Summary!$B10,'Reconciliation Request'!$B$2:$B$755,Summary!$C10,'Reconciliation Request'!$K$2:$K$755,R$3) -> 29 | S10: =COUNTIFS('Reconciliation Request'!$A$2:$A$755,Summary!$B10,'Reconciliation Request'!$B$2:$B$755,Summary!$C10,'Reconciliation Request'!$K$2:$K$755,S$3) -> 28 | T10: =COUNTIFS('Reconciliation Request'!$A$2:$A$755,Summary!$B10,'Reconciliation Request'!$B$2:$B$755,Summary!$C10,'Reconciliation Request'!$K$2:$K$755,T$3) -> 0
B11: Travel | C11: Acquisition | D11: =COUNTIFS('Reconciliation Request'!$A$2:$A$755,Summary!$B11,'Reconciliation Request'!$B$2:$B$755,Summary!$C11,'Reconciliation Request'!$F$2:$F$755,"=1") -> 6 | E11: =COUNTIFS('Reconciliation Request'!$A$2:$A$755,Summary!$B11,'Reconciliation Request'!$B$2:$B$755,Summary!$C11,'Reconciliation Request'!$J$2:$J$755,Summary!E$3,'Reconciliation Request'!$F$2:$F$755,"=1") -> 0 | F11: =COUNTIFS('Reconciliation Request'!$A$2:$A$755,Summary!$B11,'Reconciliation Request'!$B$2:$B$755,Summary!$C11,'Reconciliation Request'!$J$2:$J$755,Summary!F$3,'Reconciliation Request'!$F$2:$F$755,"=1") -> 1 | G11: =COUNTIFS('Reconciliation Request'!$A$2:$A$755,Summary!$B11,'Reconciliation Request'!$B$2:$B$755,Summary!$C11,'Reconciliation Request'!$J$2:$J$755,Summary!G$3,'Reconciliation Request'!$F$2:$F$755,"=1") -> 1 | H11: =COUNTIFS('Reconciliation Request'!$A$2:$A$755,Summary!$B11,'Reconciliation Request'!$B$2:$B$755,Summary!$C11,'Reconciliation Request'!$J$2:$J$755,Summary!H$3,'Reconciliation Request'!$F$2:$F$755,"=1") -> 4 | I11: 3 | J11: =COUNTIFS('Reconciliation Request'!$A$2:$A$755,Summary!$B11,'Reconciliation Request'!$B$2:$B$755,Summary!$C11,'Reconciliation Request'!$H$2:$H$755,">0",'Reconciliation Request'!$F$2:$F$755,"=1") -> 3 | K11: =I11/D11 -> 0.5 | L11: =J11/D11 -> 0.5 | M11: =COUNTIFS('Reconciliation Request'!$A$2:$A$755,Summary!$B11,'Reconciliation Request'!$B$2:$B$755,Summary!$C11,'Reconciliation Request'!$F$2:$F$755,"<>1") -> 16 | N11: =M11+D11 -> 22 | O11: =COUNTIFS('Reconciliation Request'!$A$2:$A$755,Summary!$B11,'Reconciliation Request'!$B$2:$B$755,Summary!$C11,'Reconciliation Request'!$H$2:$H$755,">0") -> 5 | P11: =N11-O11 -> 17 | Q11: =O11/N11 -> 0.22727273 | R11: =COUNTIFS('Reconciliation Request'!$A$2:$A$755,Summary!$B11,'Reconciliation Request'!$B$2:$B$755,Summary!$C11,'Reconciliation Request'!$K$2:$K$755,R$3) -> 9 | S11: =COUNTIFS('Reconciliation Request'!$A$2:$A$755,Summary!$B11,'Reconciliation Request'!$B$2:$B$755,Summary!$C11,'Reconciliation Request'!$K$2:$K$755,S$3) -> 9 | T11: =COUNTIFS('Reconciliation Request'!$A$2:$A$755,Summary!$B11,'Reconciliation Request'!$B$2:$B$755,Summary!$C11,'Reconciliation Request'!$K$2:$K$755,T$3) -> 4
B12: Travel | C12: Renewal | D12: =COUNTIFS('Reconciliation Request'!$A$2:$A$755,Summary!$B12,'Reconciliation Request'!$B$2:$B$755,Summary!$C12,'Reconciliation Request'!$F$2:$F$755,"=1") -> 6 | E12: =COUNTIFS('Reconciliation Request'!$A$2:$A$755,Summary!$B12,'Reconciliation Request'!$B$2:$B$755,Summary!$C12,'Reconciliation Request'!$J$2:$J$755,Summary!E$3,'Reconciliation Request'!$F$2:$F$755,"=1") -> 0 | F12: =COUNTIFS('Reconciliation Request'!$A$2:$A$755,Summary!$B12,'Reconciliation Request'!$B$2:$B$755,Summary!$C12,'Reconciliation Request'!$J$2:$J$755,Summary!F$3,'Reconciliation Request'!$F$2:$F$755,"=1") -> 2 | G12: =COUNTIFS('Reconciliation Request'!$A$2:$A$755,Summary!$B12,'Reconciliation Request'!$B$2:$B$755,Summary!$C12,'Reconciliation Request'!$J$2:$J$755,Summary!G$3,'Reconciliation Request'!$F$2:$F$755,"=1") -> 0 | H12: =COUNTIFS('Reconciliation Request'!$A$2:$A$755,Summary!$B12,'Reconciliation Request'!$B$2:$B$755,Summary!$C12,'Reconciliation Request'!$J$2:$J$755,Summary!H$3,'Reconciliation Request'!$F$2:$F$755,"=1") -> 4 | I12: 2 | J12: =COUNTIFS('Reconciliation Request'!$A$2:$A$755,Summary!$B12,'Reconciliation Request'!$B$2:$B$755,Summary!$C12,'Reconciliation Request'!$H$2:$H$755,">0",'Reconciliation Request'!$F$2:$F$755,"=1") -> 4 | K12: =I12/D12 -> 0.33333333 | L12: =J12/D12 -> 0.66666667 | M12: =COUNTIFS('Reconciliation Request'!$A$2:$A$755,Summary!$B12,'Reconciliation Request'!$B$2:$B$755,Summary!$C12,'Reconciliation Request'!$F$2:$F$755,"<>1") -> 13 | N12: =M12+D12 -> 19 | O12: =COUNTIFS('Reconciliation Request'!$A$2:$A$755,Summary!$B12,'Reconciliation Request'!$B$2:$B$755,Summary!$C12,'Reconciliation Request'!$H$2:$H$755,">0") -> 4 | P12: =N12-O12 -> 15 | Q12: =O12/N12 -> 0.21052632 | R12: =COUNTIFS('Reconciliation Request'!$A$2:$A$755,Summary!$B12,'Reconciliation Request'!$B$2:$B$755,Summary!$C12,'Reconciliation Request'!$K$2:$K$755,R$3) -> 5 | S12: =COUNTIFS('Reconciliation Request'!$A$2:$A$755,Summary!$B12,'Reconciliation Request'!$B$2:$B$755,Summary!$C12,'Reconciliation Request'!$K$2:$K$755,S$3) -> 12 | T12: =COUNTIFS('Reconciliation Request'!$A$2:$A$755,Summary!$B12,'Reconciliation Request'!$B$2:$B$755,Summary!$C12,'Reconciliation Request'!$K$2:$K$755,T$3) -> 2
J13: =COUNTIFS('Reconciliation Request'!$A$2:$A$755,Summary!$B13,'Reconciliation Request'!$B$2:$B$755,Summary!$C13,'Reconciliation Request'!$H$2:$H$755,">0",'Reconciliation Request'!$F$2:$F$755,"=1") -> 0 | N13: =M13+D13 -> 0
J14: =COUNTIFS('Reconciliation Request'!$A$2:$A$755,Summary!$B14,'Reconciliation Request'!$B$2:$B$755,Summary!$C14,'Reconciliation Request'!$H$2:$H$755,">0",'Reconciliation Request'!$F$2:$F$755,"=1") -> 0 | N14: =M14+D14 -> 0
B15: Home | C15: MTA | D15: =COUNTIFS('Reconciliation Request'!$A$2:$A$755,Summary!$B15,'Reconciliation Request'!$B$2:$B$755,Summary!$C15,'Reconciliation Request'!$F$2:$F$755,"=1") -> 4 | E15: =COUNTIFS('Reconciliation Request'!$A$2:$A$755,Summary!$B15,'Reconciliation Request'!$B$2:$B$755,Summary!$C15,'Reconciliation Request'!$J$2:$J$755,Summary!E$3,'Reconciliation Request'!$F$2:$F$755,"=1") -> 0 | F15: =COUNTIFS('Reconciliation Request'!$A$2:$A$755,Summary!$B15,'Reconciliation Request'!$B$2:$B$755,Summary!$C15,'Reconciliation Request'!$J$2:$J$755,Summary!F$3,'Reconciliation Request'!$F$2:$F$755,"=1") -> 0 | G15: =COUNTIFS('Reconciliation Request'!$A$2:$A$755,Summary!$B15,'Reconciliation Request'!$B$2:$B$755,Summary!$C15,'Reconciliation Request'!$J$2:$J$755,Summary!G$3,'Reconciliation Request'!$F$2:$F$755,"=1") -> 0 | H15: =COUNTIFS('Reconciliation Request'!$A$2:$A$755,Summary!$B15,'Reconciliation Request'!$B$2:$B$755,Summary!$C15,'Reconciliation Request'!$J$2:$J$755,Summary!H$3,'Reconciliation Request'!$F$2:$F$755,"=1") -> 4 | I15: 0 | J15: 4 | K15: =I15/D15 -> 0 | L15: =J15/D15 -> 1 | M15: =COUNTIFS('Reconciliation Request'!$A$2:$A$755,Summary!$B15,'Reconciliation Request'!$B$2:$B$755,Summary!$C15,'Reconciliation Request'!$F$2:$F$755,"<>1") -> 40 | N15: =M15+D15 -> 44 | O15: =COUNTIFS('Reconciliation Request'!$A$2:$A$755,Summary!$B15,'Reconciliation Request'!$B$2:$B$755,Summary!$C15,'Reconciliation Request'!$H$2:$H$755,">0") -> 23 | P15: =N15-O15 -> 21 | Q15: =O15/N15 -> 0.52272727 | R15: =COUNTIFS('Reconciliation Request'!$A$2:$A$755,Summary!$B15,'Reconciliation Request'!$B$2:$B$755,Summary!$C15,'Reconciliation Request'!$K$2:$K$755,R$3) -> 24 | S15: =COUNTIFS('Reconciliation Request'!$A$2:$A$755,Summary!$B15,'Reconciliation Request'!$B$2:$B$755,Summary!$C15,'Reconciliation Request'!$K$2:$K$755,S$3) -> 17 | T15: =COUNTIFS('Reconciliation Request'!$A$2:$A$755,Summary!$B15,'Reconciliation Request'!$B$2:$B$755,Summary!$C15,'Reconciliation Request'!$K$2:$K$755,T$3) -> 3
B16: Home | C16: Cancellation | D16: =COUNTIFS('Reconciliation Request'!$A$2:$A$755,Summary!$B16,'Reconciliation Request'!$B$2:$B$755,Summary!$C16,'Reconciliation Request'!$F$2:$F$755,"=1") -> 3 | E16: =COUNTIFS('Reconciliation Request'!$A$2:$A$755,Summary!$B16,'Reconciliation Request'!$B$2:$B$755,Summary!$C16,'Reconciliation Request'!$J$2:$J$755,Summary!E$3,'Reconciliation Request'!$F$2:$F$755,"=1") -> 0 | F16: =COUNTIFS('Reconciliation Request'!$A$2:$A$755,Summary!$B16,'Reconciliation Request'!$B$2:$B$755,Summary!$C16,'Reconciliation Request'!$J$2:$J$755,Summary!F$3,'Reconciliation Request'!$F$2:$F$755,"=1") -> 0 | G16: =COUNTIFS('Reconciliation Request'!$A$2:$A$755,Summary!$B16,'Reconciliation Request'!$B$2:$B$755,Summary!$C16,'Reconciliation Request'!$J$2:$J$755,Summary!G$3,'Reconciliation Request'!$F$2:$F$755,"=1") -> 0 | H16: =COUNTIFS('Reconciliation Request'!$A$2:$A$755,Summary!$B16,'Reconciliation Request'!$B$2:$B$755,Summary!$C16,'Reconciliation Request'!$J$2:$J$755,Summary!H$3,'Reconciliation Request'!$F$2:$F$755,"=1") -> 3 | I16: 1 | J16: 3 | K16: =I16/D16 -> 0.33333333 | L16: =J16/D16 -> 1 | M16: =COUNTIFS('Reconciliation Request'!$A$2:$A$755,Summary!$B16,'Reconciliation Request'!$B$2:$B$755,Summary!$C16,'Reconciliation Request'!$F$2:$F$755,"<>1") -> 20 | N16: =M16+D16 -> 23 | O16: =COUNTIFS('Reconciliation Request'!$A$2:$A$755,Summary!$B16,'Reconciliation Request'!$B$2:$B$755,Summary!$C16,'Reconciliation Request'!$H$2:$H$755,">0") -> 6 | P16: =N16-O16 -> 17 | Q16: =O16/N16 -> 0.26086957 | R16: =COUNTIFS('Reconciliation Request'!$A$2:$A$755,Summary!$B16,'Reconciliation Request'!$B$2:$B$755,Summary!$C16,'Reconciliation Request'!$K$2:$K$755,R$3) -> 16 | S16: =COUNTIFS('Reconciliation Request'!$A$2:$A$755,Summary!$B16,'Reconciliation Request'!$B$2:$B$755,Summary!$C16,'Reconciliation Request'!$K$2:$K$755,S$3) -> 6 | T16: =COUNTIFS('Reconciliation Request'!$A$2:$A$755,Summary!$B16,'Reconciliation Request'!$B$2:$B$755,Summary!$C16,'Reconciliation Request'!$K$2:$K$755,T$3) -> 1
B17: Home | C17: Arrears | D17: =COUNTIFS('Reconciliation Request'!$A$2:$A$755,Summary!$B17,'Reconciliation Request'!$B$2:$B$755,Summary!$C17,'Reconciliation Request'!$F$2:$F$755,"=1") -> 3 | E17: =COUNTIFS('Reconciliation Request'!$A$2:$A$755,Summary!$B17,'Reconciliation Request'!$B$2:$B$755,Summary!$C17,'Reconciliation Request'!$J$2:$J$755,Summary!E$3,'Reconciliation Request'!$F$2:$F$755,"=1") -> 0 | F17: =COUNTIFS('Reconciliation Request'!$A$2:$A$755,Summary!$B17,'Reconciliation Request'!$B$2:$B$755,Summary!$C17,'Reconciliation Request'!$J$2:$J$755,Summary!F$3,'Reconciliation Request'!$F$2:$F$755,"=1") -> 0 | G17: =COUNTIFS('Reconciliation Request'!$A$2:$A$755,Summary!$B17,'Reconciliation Request'!$B$2:$B$755,Summary!$C17,'Reconciliation Request'!$J$2:$J$755,Summary!G$3,'Reconciliation Request'!$F$2:$F$755,"=1") -> 0 | H17: =COUNTIFS('Reconciliation Request'!$A$2:$A$755,Summary!$B17,'Reconciliation Request'!$B$2:$B$755,Summary!$C17,'Reconciliation Request'!$J$2:$J$755,Summary!H$3,'Reconciliation Request'!$F$2:$F$755,"=1") -> 3 | I17: 1 | J17: 2 | K17: =I17/D17 -> 0.33333333 | L17: =J17/D17 -> 0.66666667 | M17: =COUNTIFS('Reconciliation Request'!$A$2:$A$755,Summary!$B17,'Reconciliation Request'!$B$2:$B$755,Summary!$C17,'Reconciliation Request'!$F$2:$F$755,"<>1") -> 12 | N17: =M17+D17 -> 15 | O17: =COUNTIFS('Reconciliation Request'!$A$2:$A$755,Summary!$B17,'Reconciliation Request'!$B$2:$B$755,Summary!$C17,'Reconciliation Request'!$H$2:$H$755,">0") -> 4 | P17: =N17-O17 -> 11 | Q17: =O17/N17 -> 0.26666667 | R17: =COUNTIFS('Reconciliation Request'!$A$2:$A$755,Summary!$B17,'Reconciliation Request'!$B$2:$B$755,Summary!$C17,'Reconciliation Request'!$K$2:$K$755,R$3) -> 5 | S17: =COUNTIFS('Reconciliation Request'!$A$2:$A$755,Summary!$B17,'Reconciliation Request'!$B$2:$B$755,Summary!$C17,'Reconciliation Request'!$K$2:$K$755,S$3) -> 8 | T17: =COUNTIFS('Reconciliation Request'!$A$2:$A$755,Summary!$B17,'Reconciliation Request'!$B$2:$B$755,Summary!$C17,'Reconciliation Request'!$K$2:$K$755,T$3) -> 1
B18: Home | C18: Doc Request | D18: =COUNTIFS('Reconciliation Request'!$A$2:$A$755,Summary!$B18,'Reconciliation Request'!$B$2:$B$755,Summary!$C18,'Reconciliation Request'!$F$2:$F$755,"=1") -> 2 | E18: =COUNTIFS('Reconciliation Request'!$A$2:$A$755,Summary!$B18,'Reconciliation Request'!$B$2:$B$755,Summary!$C18,'Reconciliation Request'!$J$2:$J$755,Summary!E$3,'Reconciliation Request'!$F$2:$F$755,"=1") -> 0 | F18: =COUNTIFS('Reconciliation Request'!$A$2:$A$755,Summary!$B18,'Reconciliation Request'!$B$2:$B$755,Summary!$C18,'Reconciliation Request'!$J$2:$J$755,Summary!F$3,'Reconciliation Request'!$F$2:$F$755,"=1") -> 0 | G18: =COUNTIFS('Reconciliation Request'!$A$2:$A$755,Summary!$B18,'Reconciliation Request'!$B$2:$B$755,Summary!$C18,'Reconciliation Request'!$J$2:$J$755,Summary!G$3,'Reconciliation Request'!$F$2:$F$755,"=1") -> 0 | H18: =COUNTIFS('Reconciliation Request'!$A$2:$A$755,Summary!$B18,'Reconciliation Request'!$B$2:$B$755,Summary!$C18,'Reconciliation Request'!$J$2:$J$755,Summary!H$3,'Reconciliation Request'!$F$2:$F$755,"=1") -> 2 | I18: 1 | J18: =COUNTIFS('Reconciliation Request'!$A$2:$A$755,Summary!$B18,'Reconciliation Request'!$B$2:$B$755,Summary!$C18,'Reconciliation Request'!$H$2:$H$755,">0",'Reconciliation Request'!$F$2:$F$755,"=1") -> 2 | K18: =I18/D18 -> 0.5 | L18: =J18/D18 -> 1 | M18: =COUNTIFS('Reconciliation Request'!$A$2:$A$755,Summary!$B18,'Reconciliation Request'!$B$2:$B$755,Summary!$C18,'Reconciliation Request'!$F$2:$F$755,"<>1") -> 12 | N18: =M18+D18 -> 14 | O18: =COUNTIFS('Reconciliation Request'!$A$2:$A$755,Summary!$B18,'Reconciliation Request'!$B$2:$B$755,Summary!$C18,'Reconciliation Request'!$H$2:$H$755,">0") -> 5 | P18: =N18-O18 -> 9 | Q18: =O18/N18 -> 0.35714286 | R18: =COUNTIFS('Reconciliation Request'!$A$2:$A$755,Summary!$B18,'Reconciliation Request'!$B$2:$B$755,Summary!$C18,'Reconciliation Request'!$K$2:$K$755,R$3) -> 4 | S18: =COUNTIFS('Reconciliation Request'!$A$2:$A$755,Summary!$B18,'Reconciliation Request'!$B$2:$B$755,Summary!$C18,'Reconciliation Request'!$K$2:$K$755,S$3) -> 0 | T18: =COUNTIFS('Reconciliation Request'!$A$2:$A$755,Summary!$B18,'Reconciliation Request'!$B$2:$B$755,Summary!$C18,'Reconciliation Request'!$K$2:$K$755,T$3) -> 2
B19: Home | C19: In-Life | D19: =COUNTIFS('Reconciliation Request'!$A$2:$A$755,Summary!$B19,'Reconciliation Request'!$B$2:$B$755,Summary!$C19,'Reconciliation Request'!$F$2:$F$755,"=1") -> 1 | E19: =COUNTIFS('Reconciliation Request'!$A$2:$A$755,Summary!$B19,'Reconciliation Request'!$B$2:$B$755,Summary!$C19,'Reconciliation Request'!$J$2:$J$755,Summary!E$3,'Reconciliation Request'!$F$2:$F$755,"=1") -> 0 | F19: =COUNTIFS('Reconciliation Request'!$A$2:$A$755,Summary!$B19,'Reconciliation Request'!$B$2:$B$755,Summary!$C19,'Reconciliation Request'!$J$2:$J$755,Summary!F$3,'Reconciliation Request'!$F$2:$F$755,"=1") -> 0 | G19: =COUNTIFS('Reconciliation Request'!$A$2:$A$755,Summary!$B19,'Reconciliation Request'!$B$2:$B$755,Summary!$C19,'Reconciliation Request'!$J$2:$J$755,Summary!G$3,'Reconciliation Request'!$F$2:$F$755,"=1") -> 0 | H19: =COUNTIFS('Reconciliation Request'!$A$2:$A$755,Summary!$B19,'Reconciliation Request'!$B$2:$B$755,Summary!$C19,'Reconciliation Request'!$J$2:$J$755,Summary!H$3,'Reconciliation Request'!$F$2:$F$755,"=1") -> 1 | J19: =COUNTIFS('Reconciliation Request'!$A$2:$A$755,Summary!$B19,'Reconciliation Request'!$B$2:$B$755,Summary!$C19,'Reconciliation Request'!$H$2:$H$755,">0",'Reconciliation Request'!$F$2:$F$755,"=1") -> 0 | K19: =I19/D19 -> 0 | L19: =J19/D19 -> 0 | M19: =COUNTIFS('Reconciliation Request'!$A$2:$A$755,Summary!$B19,'Reconciliation Request'!$B$2:$B$755,Summary!$C19,'Reconciliation Request'!$F$2:$F$755,"<>1") -> 0 | N19: =M19+D19 -> 1 | O19: =COUNTIFS('Reconciliation Request'!$A$2:$A$755,Summary!$B19,'Reconciliation Request'!$B$2:$B$755,Summary!$C19,'Reconciliation Request'!$H$2:$H$755,">0") -> 0 | P19: =N19-O19 -> 1 | Q19: =O19/N19 -> 0 | R19: =COUNTIFS('Reconciliation Request'!$A$2:$A$755,Summary!$B19,'Reconciliation Request'!$B$2:$B$755,Summary!$C19,'Reconciliation Request'!$K$2:$K$755,R$3) -> 0 | S19: =COUNTIFS('Reconciliation Request'!$A$2:$A$755,Summary!$B19,'Reconciliation Request'!$B$2:$B$755,Summary!$C19,'Reconciliation Request'!$K$2:$K$755,S$3) -> 1 | T19: =COUNTIFS('Reconciliation Request'!$A$2:$A$755,Summary!$B19,'Reconciliation Request'!$B$2:$B$755,Summary!$C19,'Reconciliation Request'!$K$2:$K$755,T$3) -> 0
B20: Home | C20: Claims | D20: =COUNTIFS('Reconciliation Request'!$A$2:$A$755,Summary!$B20,'Reconciliation Request'!$B$2:$B$755,Summary!$C20,'Reconciliation Request'!$F$2:$F$755,"=1") -> 3 | E20: =COUNTIFS('Reconciliation Request'!$A$2:$A$755,Summary!$B20,'Reconciliation Request'!$B$2:$B$755,Summary!$C20,'Reconciliation Request'!$J$2:$J$755,Summary!E$3,'Reconciliation Request'!$F$2:$F$755,"=1") -> 0 | F20: =COUNTIFS('Reconciliation Request'!$A$2:$A$755,Summary!$B20,'Reconciliation Request'!$B$2:$B$755,Summary!$C20,'Reconciliation Request'!$J$2:$J$755,Summary!F$3,'Reconciliation Request'!$F$2:$F$755,"=1") -> 0 | G20: =COUNTIFS('Reconciliation Request'!$A$2:$A$755,Summary!$B20,'Reconciliation Request'!$B$2:$B$755,Summary!$C20,'Reconciliation Request'!$J$2:$J$755,Summary!G$3,'Reconciliation Request'!$F$2:$F$755,"=1") -> 0 | H20: =COUNTIFS('Reconciliation Request'!$A$2:$A$755,Summary!$B20,'Reconciliation Request'!$B$2:$B$755,Summary!$C20,'Reconciliation Request'!$J$2:$J$755,Summary!H$3,'Reconciliation Request'!$F$2:$F$755,"=1") -> 3 | I20: 0 | J20: 3 | K20: =I20/D20 -> 0 | L20: =J20/D20 -> 1 | M20: =COUNTIFS('Reconciliation Request'!$A$2:$A$755,Summary!$B20,'Reconciliation Request'!$B$2:$B$755,Summary!$C20,'Reconciliation Request'!$F$2:$F$755,"<>1") -> 8 | N20: =M20+D20 -> 11 | O20: =COUNTIFS('Reconciliation Request'!$A$2:$A$755,Summary!$B20,'Reconciliation Request'!$B$2:$B$755,Summary!$C20,'Reconciliation Request'!$H$2:$H$755,">0") -> 5 | P20: =N20-O20 -> 6 | Q20: =O20/N20 -> 0.45454545 | R20: =COUNTIFS('Reconciliation Request'!$A$2:$A$755,Summary!$B20,'Reconciliation Request'!$B$2:$B$755,Summary!$C20,'Reconciliation Request'!$K$2:$K$755,R$3) -> 7 | S20: =COUNTIFS('Reconciliation Request'!$A$2:$A$755,Summary!$B20,'Reconciliation Request'!$B$2:$B$755,Summary!$C20,'Reconciliation Request'!$K$2:$K$755,S$3) -> 4 | T20: =COUNTIFS('Reconciliation Request'!$A$2:$A$755,Summary!$B20,'Reconciliation Request'!$B$2:$B$755,Summary!$C20,'Reconciliation Request'!$K$2:$K$755,T$3) -> 0
B21: Motor | C21: MTA | D21: =COUNTIFS('Reconciliation Request'!$A$2:$A$755,Summary!$B21,'Reconciliation Request'!$B$2:$B$755,Summary!$C21,'Reconciliation Request'!$F$2:$F$755,"=1") -> 6 | E21: =COUNTIFS('Reconciliation Request'!$A$2:$A$755,Summary!$B21,'Reconciliation Request'!$B$2:$B$755,Summary!$C21,'Reconciliation Request'!$J$2:$J$755,Summary!E$3,'Reconciliation Request'!$F$2:$F$755,"=1") -> 0 | F21: =COUNTIFS('Reconciliation Request'!$A$2:$A$755,Summary!$B21,'Reconciliation Request'!$B$2:$B$755,Summary!$C21,'Reconciliation Request'!$J$2:$J$755,Summary!F$3,'Reconciliation Request'!$F$2:$F$755,"=1") -> 1 | G21: =COUNTIFS('Reconciliation Request'!$A$2:$A$755,Summary!$B21,'Reconciliation Request'!$B$2:$B$755,Summary!$C21,'Reconciliation Request'!$J$2:$J$755,Summary!G$3,'Reconciliation Request'!$F$2:$F$755,"=1") -> 0 | H21: =COUNTIFS('Reconciliation Request'!$A$2:$A$755,Summary!$B21,'Reconciliation Request'!$B$2:$B$755,Summary!$C21,'Reconciliation Request'!$J$2:$J$755,Summary!H$3,'Reconciliation Request'!$F$2:$F$755,"=1") -> 5 | I21: 1 | J21: 5 | K21: =I21/D21 -> 0.16666667 | L21: =J21/D21 -> 0.83333333 | M21: =COUNTIFS('Reconciliation Request'!$A$2:$A$755,Summary!$B21,'Reconciliation Request'!$B$2:$B$755,Summary!$C21,'Reconciliation Request'!$F$2:$F$755,"<>1") -> 37 | N21: =M21+D21 -> 43 | O21: =COUNTIFS('Reconciliation Request'!$A$2:$A$755,Summary!$B21,'Reconciliation Request'!$B$2:$B$755,Summary!$C21,'Reconciliation Request'!$H$2:$H$755,">0") -> 17 | P21: =N21-O21 -> 26 | Q21: =O21/N21 -> 0.39534884 | R21: =COUNTIFS('Reconciliation Request'!$A$2:$A$755,Summary!$B21,'Reconciliation Request'!$B$2:$B$755,Summary!$C21,'Reconciliation Request'!$K$2:$K$755,R$3) -> 25 | S21: =COUNTIFS('Reconciliation Request'!$A$2:$A$755,Summary!$B21,'Reconciliation Request'!$B$2:$B$755,Summary!$C21,'Reconciliation Request'!$K$2:$K$755,S$3) -> 16 | T21: =COUNTIFS('Reconciliation Request'!$A$2:$A$755,Summary!$B21,'Reconciliation Request'!$B$2:$B$755,Summary!$C21,'Reconciliation Request'!$K$2:$K$755,T$3) -> 2
B22: Motor | C22: Cancellation | D22: =COUNTIFS('Reconciliation Request'!$A$2:$A$755,Summary!$B22,'Reconciliation Request'!$B$2:$B$755,Summary!$C22,'Reconciliation Request'!$F$2:$F$755,"=1") -> 6 | E22: =COUNTIFS('Reconciliation Request'!$A$2:$A$755,Summary!$B22,'Reconciliation Request'!$B$2:$B$755,Summary!$C22,'Reconciliation Request'!$J$2:$J$755,Summary!E$3,'Reconciliation Request'!$F$2:$F$755,"=1") -> 0 | F22: =COUNTIFS('Reconciliation Request'!$A$2:$A$755,Summary!$B22,'Reconciliation Request'!$B$2:$B$755,Summary!$C22,'Reconciliation Request'!$J$2:$J$755,Summary!F$3,'Reconciliation Request'!$F$2:$F$755,"=1") -> 0 | G22: =COUNTIFS('Reconciliation Request'!$A$2:$A$755,Summary!$B22,'Reconciliation Request'!$B$2:$B$755,Summary!$C22,'Reconciliation Request'!$J$2:$J$755,Summary!G$3,'Reconciliation Request'!$F$2:$F$755,"=1") -> 0 | H22: =COUNTIFS('Reconciliation Request'!$A$2:$A$755,Summary!$B22,'Reconciliation Request'!$B$2:$B$755,Summary!$C22,'Reconciliation Request'!$J$2:$J$755,Summary!H$3,'Reconciliation Request'!$F$2:$F$755,"=1") -> 6 | I22: 1 | J22: 5 | K22: =I22/D22 -> 0.16666667 | L22: =J22/D22 -> 0.83333333 | M22: =COUNTIFS('Reconciliation Request'!$A$2:$A$755,Summary!$B22,'Reconciliation Request'!$B$2:$B$755,Summary!$C22,'Reconciliation Request'!$F$2:$F$755,"<>1") -> 10 | N22: =M22+D22 -> 16 | O22: =COUNTIFS('Reconciliation Request'!$A$2:$A$755,Summary!$B22,'Reconciliation Request'!$B$2:$B$755,Summary!$C22,'Reconciliation Request'!$H$2:$H$755,">0") -> 7 | P22: =N22-O22 -> 9 | Q22: =O22/N22 -> 0.4375 | R22: =COUNTIFS('Reconciliation Request'!$A$2:$A$755,Summary!$B22,'Reconciliation Request'!$B$2:$B$755,Summary!$C22,'Reconciliation Request'!$K$2:$K$755,R$3) -> 9 | S22: =COUNTIFS('Reconciliation Request'!$A$2:$A$755,Summary!$B22,'Reconciliation Request'!$B$2:$B$755,Summary!$C22,'Reconciliation Request'!$K$2:$K$755,S$3) -> 5 | T22: =COUNTIFS('Reconciliation Request'!$A$2:$A$755,Summary!$B22,'Reconciliation Request'!$B$2:$B$755,Summary!$C22,'Reconciliation Request'!$K$2:$K$755,T$3) -> 2
B23: Motor | C23: Arrears | D23: =COUNTIFS('Reconciliation Request'!$A$2:$A$755,Summary!$B23,'Reconciliation Request'!$B$2:$B$755,Summary!$C23,'Reconciliation Request'!$F$2:$F$755,"=1") -> 3 | E23: =COUNTIFS('Reconciliation Request'!$A$2:$A$755,Summary!$B23,'Reconciliation Request'!$B$2:$B$755,Summary!$C23,'Reconciliation Request'!$J$2:$J$755,Summary!E$3,'Reconciliation Request'!$F$2:$F$755,"=1") -> 0 | F23: =COUNTIFS('Reconciliation Request'!$A$2:$A$755,Summary!$B23,'Reconciliation Request'!$B$2:$B$755,Summary!$C23,'Reconciliation Request'!$J$2:$J$755,Summary!F$3,'Reconciliation Request'!$F$2:$F$755,"=1") -> 0 | G23: =COUNTIFS('Reconciliation Request'!$A$2:$A$755,Summary!$B23,'Reconciliation Request'!$B$2:$B$755,Summary!$C23,'Reconciliation Request'!$J$2:$J$755,Summary!G$3,'Reconciliation Request'!$F$2:$F$755,"=1") -> 0 | H23: =COUNTIFS('Reconciliation Request'!$A$2:$A$755,Summary!$B23,'Reconciliation Request'!$B$2:$B$755,Summary!$C23,'Reconciliation Request'!$J$2:$J$755,Summary!H$3,'Reconciliation Request'!$F$2:$F$755,"=1") -> 3 | I23: 1 | J23: 2 | K23: =I23/D23 -> 0.33333333 | L23: =J23/D23 -> 0.66666667 | M23: =COUNTIFS('Reconciliation Request'!$A$2:$A$755,Summary!$B23,'Reconciliation Request'!$B$2:$B$755,Summary!$C23,'Reconciliation Request'!$F$2:$F$755,"<>1") -> 12 | N23: =M23+D23 -> 15 | O23: =COUNTIFS('Reconciliation Request'!$A$2:$A$755,Summary!$B23,'Reconciliation Request'!$B$2:$B$755,Summary!$C23,'Reconciliation Request'!$H$2:$H$755,">0") -> 5 | P23: =N23-O23 -> 10 | Q23: =O23/N23 -> 0.33333333 | R23: =COUNTIFS('Reconciliation Request'!$A$2:$A$755,Summary!$B23,'Reconciliation Request'!$B$2:$B$755,Summary!$C23,'Reconciliation Request'!$K$2:$K$755,R$3) -> 5 | S23: =COUNTIFS('Reconciliation Request'!$A$2:$A$755,Summary!$B23,'Reconciliation Request'!$B$2:$B$755,Summary!$C23,'Reconciliation Request'!$K$2:$K$755,S$3) -> 8 | T23: =COUNTIFS('Reconciliation Request'!$A$2:$A$755,Summary!$B23,'Reconciliation Request'!$B$2:$B$755,Summary!$C23,'Reconciliation Request'!$K$2:$K$755,T$3) -> 2
B24: Motor | C24: In-Life | D24: =COUNTIFS('Reconciliation Request'!$A$2:$A$755,Summary!$B24,'Reconciliation Request'!$B$2:$B$755,Summary!$C24,'Reconciliation Request'!$F$2:$F$755,"=1") -> 1 | E24: =COUNTIFS('Reconciliation Request'!$A$2:$A$755,Summary!$B24,'Reconciliation Request'!$B$2:$B$755,Summary!$C24,'Reconciliation Request'!$J$2:$J$755,Summary!E$3,'Reconciliation Request'!$F$2:$F$755,"=1") -> 0 | F24: =COUNTIFS('Reconciliation Request'!$A$2:$A$755,Summary!$B24,'Reconciliation Request'!$B$2:$B$755,Summary!$C24,'Reconciliation Request'!$J$2:$J$755,Summary!F$3,'Reconciliation Request'!$F$2:$F$755,"=1") -> 0 | G24: =COUNTIFS('Reconciliation Request'!$A$2:$A$755,Summary!$B24,'Reconciliation Request'!$B$2:$B$755,Summary!$C24,'Reconciliation Request'!$J$2:$J$755,Summary!G$3,'Reconciliation Request'!$F$2:$F$755,"=1") -> 0 | H24: =COUNTIFS('Reconciliation Request'!$A$2:$A$755,Summary!$B24,'Reconciliation Request'!$B$2:$B$755,Summary!$C24,'Reconciliation Request'!$J$2:$J$755,Summary!H$3,'Reconciliation Request'!$F$2:$F$755,"=1") -> 1 | J24: =COUNTIFS('Reconciliation Request'!$A$2:$A$755,Summary!$B24,'Reconciliation Request'!$B$2:$B$755,Summary!$C24,'Reconciliation Request'!$H$2:$H$755,">0",'Reconciliation Request'!$F$2:$F$755,"=1") -> 0 | K24: =I24/D24 -> 0 | L24: =J24/D24 -> 0 | M24: =COUNTIFS('Reconciliation Request'!$A$2:$A$755,Summary!$B24,'Reconciliation Request'!$B$2:$B$755,Summary!$C24,'Reconciliation Request'!$F$2:$F$755,"<>1") -> 5 | N24: =M24+D24 -> 6 | O24: =COUNTIFS('Reconciliation Request'!$A$2:$A$755,Summary!$B24,'Reconciliation Request'!$B$2:$B$755,Summary!$C24,'Reconciliation Request'!$H$2:$H$755,">0") -> 0 | P24: =N24-O24 -> 6 | Q24: =O24/N24 -> 0 | R24: =COUNTIFS('Reconciliation Request'!$A$2:$A$755,Summary!$B24,'Reconciliation Request'!$B$2:$B$755,Summary!$C24,'Reconciliation Request'!$K$2:$K$755,R$3) -> 0 | S24: =COUNTIFS('Reconciliation Request'!$A$2:$A$755,Summary!$B24,'Reconciliation Request'!$B$2:$B$755,Summary!$C24,'Reconciliation Request'!$K$2:$K$755,S$3) -> 6 | T24: =COUNTIFS('Reconciliation Request'!$A$2:$A$755,Summary!$B24,'Reconciliation Request'!$B$2:$B$755,Summary!$C24,'Reconciliation Request'!$K$2:$K$755,T$3) -> 0
B25: Motor | C25: Claims | D25: =COUNTIFS('Reconciliation Request'!$A$2:$A$755,Summary!$B25,'Reconciliation Request'!$B$2:$B$755,Summary!$C25,'Reconciliation Request'!$F$2:$F$755,"=1") -> 4 | E25: =COUNTIFS('Reconciliation Request'!$A$2:$A$755,Summary!$B25,'Reconciliation Request'!$B$2:$B$755,Summary!$C25,'Reconciliation Request'!$J$2:$J$755,Summary!E$3,'Reconciliation Request'!$F$2:$F$755,"=1") -> 0 | F25: =COUNTIFS('Reconciliation Request'!$A$2:$A$755,Summary!$B25,'Reconciliation Request'!$B$2:$B$755,Summary!$C25,'Reconciliation Request'!$J$2:$J$755,Summary!F$3,'Reconciliation Request'!$F$2:$F$755,"=1") -> 0 | G25: =COUNTIFS('Reconciliation Request'!$A$2:$A$755,Summary!$B25,'Reconciliation Request'!$B$2:$B$755,Summary!$C25,'Reconciliation Request'!$J$2:$J$755,Summary!G$3,'Reconciliation Request'!$F$2:$F$755,"=1") -> 0 | H25: =COUNTIFS('Reconciliation Request'!$A$2:$A$755,Summary!$B25,'Reconciliation Request'!$B$2:$B$755,Summary!$C25,'Reconciliation Request'!$J$2:$J$755,Summary!H$3,'Reconciliation Request'!$F$2:$F$755,"=1") -> 4 | I25: 0 | J25: 4 | K25: =I25/D25 -> 0 | L25: =J25/D25 -> 1 | M25: =COUNTIFS('Reconciliation Request'!$A$2:$A$755,Summary!$B25,'Reconciliation Request'!$B$2:$B$755,Summary!$C25,'Reconciliation Request'!$F$2:$F$755,"<>1") -> 7 | N25: =M25+D25 -> 11 | O25: =COUNTIFS('Reconciliation Request'!$A$2:$A$755,Summary!$B25,'Reconciliation Request'!$B$2:$B$755,Summary!$C25,'Reconciliation Request'!$H$2:$H$755,">0") -> 1 | P25: =N25-O25 -> 10 | Q25: =O25/N25 -> 0.090909091 | R25: =COUNTIFS('Reconciliation Request'!$A$2:$A$755,Summary!$B25,'Reconciliation Request'!$B$2:$B$755,Summary!$C25,'Reconciliation Request'!$K$2:$K$755,R$3) -> 4 | S25: =COUNTIFS('Reconciliation Request'!$A$2:$A$755,Summary!$B25,'Reconciliation Request'!$B$2:$B$755,Summary!$C25,'Reconciliation Request'!$K$2:$K$755,S$3) -> 6 | T25: =COUNTIFS('Reconciliation Request'!$A$2:$A$755,Summary!$B25,'Reconciliation Request'!$B$2:$B$755,Summary!$C25,'Reconciliation Request'!$K$2:$K$755,T$3) -> 1
B26: Motor | C26: Doc Request | D26: =COUNTIFS('Reconciliation Request'!$A$2:$A$755,Summary!$B26,'Reconciliation Request'!$B$2:$B$755,Summary!$C26,'Reconciliation Request'!$F$2:$F$755,"=1") -> 2 | E26: =COUNTIFS('Reconciliation Request'!$A$2:$A$755,Summary!$B26,'Reconciliation Request'!$B$2:$B$755,Summary!$C26,'Reconciliation Request'!$J$2:$J$755,Summary!E$3,'Reconciliation Request'!$F$2:$F$755,"=1") -> 0 | F26: =COUNTIFS('Reconciliation Request'!$A$2:$A$755,Summary!$B26,'Reconciliation Request'!$B$2:$B$755,Summary!$C26,'Reconciliation Request'!$J$2:$J$755,Summary!F$3,'Reconciliation Request'!$F$2:$F$755,"=1") -> 0 | G26: =COUNTIFS('Reconciliation Request'!$A$2:$A$755,Summary!$B26,'Reconciliation Request'!$B$2:$B$755,Summary!$C26,'Reconciliation Request'!$J$2:$J$755,Summary!G$3,'Reconciliation Request'!$F$2:$F$755,"=1") -> 0 | H26: =COUNTIFS('Reconciliation Request'!$A$2:$A$755,Summary!$B26,'Reconciliation Request'!$B$2:$B$755,Summary!$C26,'Reconciliation Request'!$J$2:$J$755,Summary!H$3,'Reconciliation Request'!$F$2:$F$755,"=1") -> 2 | I26: 0 | J26: =COUNTIFS('Reconciliation Request'!$A$2:$A$755,Summary!$B26,'Reconciliation Request'!$B$2:$B$755,Summary!$C26,'Reconciliation Request'!$H$2:$H$755,">0",'Reconciliation Request'!$F$2:$F$755,"=1") -> 2 | K26: =I26/D26 -> 0 | L26: =J26/D26 -> 1 | M26: =COUNTIFS('Reconciliation Request'!$A$2:$A$755,Summary!$B26,'Reconciliation Request'!$B$2:$B$755,Summary!$C26,'Reconciliation Request'!$F$2:$F$755,"<>1") -> 12 | N26: =M26+D26 -> 14 | O26: =COUNTIFS('Reconciliation Request'!$A$2:$A$755,Summary!$B26,'Reconciliation Request'!$B$2:$B$755,Summary!$C26,'Reconciliation Request'!$H$2:$H$755,">0") -> 6 | P26: =N26-O26 -> 8 | Q26: =O26/N26 -> 0.42857143 | R26: =COUNTIFS('Reconciliation Request'!$A$2:$A$755,Summary!$B26,'Reconciliation Request'!$B$2:$B$755,Summary!$C26,'Reconciliation Request'!$K$2:$K$755,R$3) -> 12 | S26: =COUNTIFS('Reconciliation Request'!$A$2:$A$755,Summary!$B26,'Reconciliation Request'!$B$2:$B$755,Summary!$C26,'Reconciliation Request'!$K$2:$K$755,S$3) -> 1 | T26: =COUNTIFS('Reconciliation Request'!$A$2:$A$755,Summary!$B26,'Reconciliation Request'!$B$2:$B$755,Summary!$C26,'Reconciliation Request'!$K$2:$K$755,T$3) -> 1
B27: Van | C27: MTA | D27: =COUNTIFS('Reconciliation Request'!$A$2:$A$755,Summary!$B27,'Reconciliation Request'!$B$2:$B$755,Summary!$C27,'Reconciliation Request'!$F$2:$F$755,"=1") -> 5 | E27: =COUNTIFS('Reconciliation Request'!$A$2:$A$755,Summary!$B27,'Reconciliation Request'!$B$2:$B$755,Summary!$C27,'Reconciliation Request'!$J$2:$J$755,Summary!E$3,'Reconciliation Request'!$F$2:$F$755,"=1") -> 0 | F27: =COUNTIFS('Reconciliation Request'!$A$2:$A$755,Summary!$B27,'Reconciliation Request'!$B$2:$B$755,Summary!$C27,'Reconciliation Request'!$J$2:$J$755,Summary!F$3,'Reconciliation Request'!$F$2:$F$755,"=1") -> 0 | G27: =COUNTIFS('Reconciliation Request'!$A$2:$A$755,Summary!$B27,'Reconciliation Request'!$B$2:$B$755,Summary!$C27,'Reconciliation Request'!$J$2:$J$755,Summary!G$3,'Reconciliation Request'!$F$2:$F$755,"=1") -> 0 | H27: =COUNTIFS('Reconciliation Request'!$A$2:$A$755,Summary!$B27,'Reconciliation Request'!$B$2:$B$755,Summary!$C27,'Reconciliation Request'!$J$2:$J$755,Summary!H$3,'Reconciliation Request'!$F$2:$F$755,"=1") -> 5 | I27: 2 | J27: 3 | K27: =I27/D27 -> 0.4 | L27: =J27/D27 -> 0.6 | M27: =COUNTIFS('Reconciliation Request'!$A$2:$A$755,Summary!$B27,'Reconciliation Request'!$B$2:$B$755,Summary!$C27,'Reconciliation Request'!$F$2:$F$755,"<>1") -> 39 | N27: =M27+D27 -> 44 | O27: =COUNTIFS('Reconciliation Request'!$A$2:$A$755,Summary!$B27,'Reconciliation Request'!$B$2:$B$755,Summary!$C27,'Reconciliation Request'!$H$2:$H$755,">0") -> 13 | P27: =N27-O27 -> 31 | Q27: =O27/N27 -> 0.29545455 | R27: =COUNTIFS('Reconciliation Request'!$A$2:$A$755,Summary!$B27,'Reconciliation Request'!$B$2:$B$755,Summary!$C27,'Reconciliation Request'!$K$2:$K$755,R$3) -> 21 | S27: =COUNTIFS('Reconciliation Request'!$A$2:$A$755,Summary!$B27,'Reconciliation Request'!$B$2:$B$755,Summary!$C27,'Reconciliation Request'!$K$2:$K$755,S$3) -> 20 | T27: =COUNTIFS('Reconciliation Request'!$A$2:$A$755,Summary!$B27,'Reconciliation Request'!$B$2:$B$755,Summary!$C27,'Reconciliation Request'!$K$2:$K$755,T$3) -> 3
B28: Van | C28: Cancellation | D28: =COUNTIFS('Reconciliation Request'!$A$2:$A$755,Summary!$B28,'Reconciliation Request'!$B$2:$B$755,Summary!$C28,'Reconciliation Request'!$F$2:$F$755,"=1") -> 3 | E28: =COUNTIFS('Reconciliation Request'!$A$2:$A$755,Summary!$B28,'Reconciliation Request'!$B$2:$B$755,Summary!$C28,'Reconciliation Request'!$J$2:$J$755,Summary!E$3,'Reconciliation Request'!$F$2:$F$755,"=1") -> 0 | F28: =COUNTIFS('Reconciliation Request'!$A$2:$A$755,Summary!$B28,'Reconciliation Request'!$B$2:$B$755,Summary!$C28,'Reconciliation Request'!$J$2:$J$755,Summary!F$3,'Reconciliation Request'!$F$2:$F$755,"=1") -> 0 | G28: =COUNTIFS('Reconciliation Request'!$A$2:$A$755,Summary!$B28,'Reconciliation Request'!$B$2:$B$755,Summary!$C28,'Reconciliation Request'!$J$2:$J$755,Summary!G$3,'Reconciliation Request'!$F$2:$F$755,"=1") -> 0 | H28: =COUNTIFS('Reconciliation Request'!$A$2:$A$755,Summary!$B28,'Reconciliation Request'!$B$2:$B$755,Summary!$C28,'Reconciliation Request'!$J$2:$J$755,Summary!H$3,'Reconciliation Request'!$F$2:$F$755,"=1") -> 3 | I28: 0 | J28: 3 | K28: =I28/D28 -> 0 | L28: =J28/D28 -> 1 | M28: =COUNTIFS('Reconciliation Request'!$A$2:$A$755,Summary!$B28,'Reconciliation Request'!$B$2:$B$755,Summary!$C28,'Reconciliation Request'!$F$2:$F$755,"<>1") -> 20 | N28: =M28+D28 -> 23 | O28: =COUNTIFS('Reconciliation Request'!$A$2:$A$755,Summary!$B28,'Reconciliation Request'!$B$2:$B$755,Summary!$C28,'Reconciliation Request'!$H$2:$H$755,">0") -> 6 | P28: =N28-O28 -> 17 | Q28: =O28/N28 -> 0.26086957 | R28: =COUNTIFS('Reconciliation Request'!$A$2:$A$755,Summary!$B28,'Reconciliation Request'!$B$2:$B$755,Summary!$C28,'Reconciliation Request'!$K$2:$K$755,R$3) -> 15 | S28: =COUNTIFS('Reconciliation Request'!$A$2:$A$755,Summary!$B28,'Reconciliation Request'!$B$2:$B$755,Summary!$C28,'Reconciliation Request'!$K$2:$K$755,S$3) -> 5 | T28: =COUNTIFS('Reconciliation Request'!$A$2:$A$755,Summary!$B28,'Reconciliation Request'!$B$2:$B$755,Summary!$C28,'Reconciliation Request'!$K$2:$K$755,T$3) -> 3
B29: Van | C29: Arrears | D29: =COUNTIFS('Reconciliation Request'!$A$2:$A$755,Summary!$B29,'Reconciliation Request'!$B$2:$B$755,Summary!$C29,'Reconciliation Request'!$F$2:$F$755,"=1") -> 2 | E29: =COUNTIFS('Reconciliation Request'!$A$2:$A$755,Summary!$B29,'Reconciliation Request'!$B$2:$B$755,Summary!$C29,'Reconciliation Request'!$J$2:$J$755,Summary!E$3,'Reconciliation Request'!$F$2:$F$755,"=1") -> 0 | F29: =COUNTIFS('Reconciliation Request'!$A$2:$A$755,Summary!$B29,'Reconciliation Request'!$B$2:$B$755,Summary!$C29,'Reconciliation Request'!$J$2:$J$755,Summary!F$3,'Reconciliation Request'!$F$2:$F$755,"=1") -> 0 | G29: =COUNTIFS('Reconciliation Request'!$A$2:$A$755,Summary!$B29,'Reconciliation Request'!$B$2:$B$755,Summary!$C29,'Reconciliation Request'!$J$2:$J$755,Summary!G$3,'Reconciliation Request'!$F$2:$F$755,"=1") -> 0 | H29: =COUNTIFS('Reconciliation Request'!$A$2:$A$755,Summary!$B29,'Reconciliation Request'!$B$2:$B$755,Summary!$C29,'Reconciliation Request'!$J$2:$J$755,Summary!H$3,'Reconciliation Request'!$F$2:$F$755,"=1") -> 2 | I29: 0 | J29: 2 | K29: =I29/D29 -> 0 | L29: =J29/D29 -> 1 | M29: =COUNTIFS('Reconciliation Request'!$A$2:$A$755,Summary!$B29,'Reconciliation Request'!$B$2:$B$755,Summary!$C29,'Reconciliation Request'!$F$2:$F$755,"<>1") -> 13 | N29: =M29+D29 -> 15 | O29: =COUNTIFS('Reconciliation Request'!$A$2:$A$755,Summary!$B29,'Reconciliation Request'!$B$2:$B$755,Summary!$C29,'Reconciliation Request'!$H$2:$H$755,">0") -> 4 | P29: =N29-O29 -> 11 | Q29: =O29/N29 -> 0.26666667 | R29: =COUNTIFS('Reconciliation Request'!$A$2:$A$755,Summary!$B29,'Reconciliation Request'!$B$2:$B$755,Summary!$C29,'Reconciliation Request'!$K$2:$K$755,R$3) -> 6 | S29: =COUNTIFS('Reconciliation Request'!$A$2:$A$755,Summary!$B29,'Reconciliation Request'!$B$2:$B$755,Summary!$C29,'Reconciliation Request'!$K$2:$K$755,S$3) -> 8 | T29: =COUNTIFS('Reconciliation Request'!$A$2:$A$755,Summary!$B29,'Reconciliation Request'!$B$2:$B$755,Summary!$C29,'Reconciliation Request'!$K$2:$K$755,T$3) -> 1
B30: Van | C30: In-Life | D30: =COUNTIFS('Reconciliation Request'!$A$2:$A$755,Summary!$B30,'Reconciliation Request'!$B$2:$B$755,Summary!$C30,'Reconciliation Request'!$F$2:$F$755,"=1") -> 1 | E30: =COUNTIFS('Reconciliation Request'!$A$2:$A$755,Summary!$B30,'Reconciliation Request'!$B$2:$B$755,Summary!$C30,'Reconciliation Request'!$J$2:$J$755,Summary!E$3,'Reconciliation Request'!$F$2:$F$755,"=1") -> 0 | F30: =COUNTIFS('Reconciliation Request'!$A$2:$A$755,Summary!$B30,'Reconciliation Request'!$B$2:$B$755,Summary!$C30,'Reconciliation Request'!$J$2:$J$755,Summary!F$3,'Reconciliation Request'!$F$2:$F$755,"=1") -> 0 | G30: =COUNTIFS('Reconciliation Request'!$A$2:$A$755,Summary!$B30,'Reconciliation Request'!$B$2:$B$755,Summary!$C30,'Reconciliation Request'!$J$2:$J$755,Summary!G$3,'Reconciliation Request'!$F$2:$F$755,"=1") -> 0 | H30: =COUNTIFS('Reconciliation Request'!$A$2:$A$755,Summary!$B30,'Reconciliation Request'!$B$2:$B$755,Summary!$C30,'Reconciliation Request'!$J$2:$J$755,Summary!H$3,'Reconciliation Request'!$F$2:$F$755,"=1") -> 1 | J30: =COUNTIFS('Reconciliation Request'!$A$2:$A$755,Summary!$B30,'Reconciliation Request'!$B$2:$B$755,Summary!$C30,'Reconciliation Request'!$H$2:$H$755,">0",'Reconciliation Request'!$F$2:$F$755,"=1") -> 0 | K30: =I30/D30 -> 0 | L30: =J30/D30 -> 0 | M30: =COUNTIFS('Reconciliation Request'!$A$2:$A$755,Summary!$B30,'Reconciliation Request'!$B$2:$B$755,Summary!$C30,'Reconciliation Request'!$F$2:$F$755,"<>1") -> 0 | N30: =M30+D30 -> 1 | O30: =COUNTIFS('Reconciliation Request'!$A$2:$A$755,Summary!$B30,'Reconciliation Request'!$B$2:$B$755,Summary!$C30,'Reconciliation Request'!$H$2:$H$755,">0") -> 0 | P30: =N30-O30 -> 1 | Q30: =O30/N30 -> 0 | R30: =COUNTIFS('Reconciliation Request'!$A$2:$A$755,Summary!$B30,'Reconciliation Request'!$B$2:$B$755,Summary!$C30,'Reconciliation Request'!$K$2:$K$755,R$3) -> 0 | S30: =COUNTIFS('Reconciliation Request'!$A$2:$A$755,Summary!$B30,'Reconciliation Request'!$B$2:$B$755,Summary!$C30,'Reconciliation Request'!$K$2:$K$755,S$3) -> 1 | T30: =COUNTIFS('Reconciliation Request'!$A$2:$A$755,Summary!$B30,'Reconciliation Request'!$B$2:$B$755,Summary!$C30,'Reconciliation Request'!$K$2:$K$755,T$3) -> 0
B31: Van | C31: Claims | D31: =COUNTIFS('Reconciliation Request'!$A$2:$A$755,Summary!$B31,'Reconciliation Request'!$B$2:$B$755,Summary!$C31,'Reconciliation Request'!$F$2:$F$755,"=1") -> 3 | E31: =COUNTIFS('Reconciliation Request'!$A$2:$A$755,Summary!$B31,'Reconciliation Request'!$B$2:$B$755,Summary!$C31,'Reconciliation Request'!$J$2:$J$755,Summary!E$3,'Reconciliation Request'!$F$2:$F$755,"=1") -> 0 | F31: =COUNTIFS('Reconciliation Request'!$A$2:$A$755,Summary!$B31,'Reconciliation Request'!$B$2:$B$755,Summary!$C31,'Reconciliation Request'!$J$2:$J$755,Summary!F$3,'Reconciliation Request'!$F$2:$F$755,"=1") -> 0 | G31: =COUNTIFS('Reconciliation Request'!$A$2:$A$755,Summary!$B31,'Reconciliation Request'!$B$2:$B$755,Summary!$C31,'Reconciliation Request'!$J$2:$J$755,Summary!G$3,'Reconciliation Request'!$F$2:$F$755,"=1") -> 0 | H31: =COUNTIFS('Reconciliation Request'!$A$2:$A$755,Summary!$B31,'Reconciliation Request'!$B$2:$B$755,Summary!$C31,'Reconciliation Request'!$J$2:$J$755,Summary!H$3,'Reconciliation Request'!$F$2:$F$755,"=1") -> 3 | I31: 0 | J31: 3 | K31: =I31/D31 -> 0 | L31: =J31/D31 -> 1 | M31: =COUNTIFS('Reconciliation Request'!$A$2:$A$755,Summary!$B31,'Reconciliation Request'!$B$2:$B$755,Summary!$C31,'Reconciliation Request'!$F$2:$F$755,"<>1") -> 8 | N31: =M31+D31 -> 11 | O31: =COUNTIFS('Reconciliation Request'!$A$2:$A$755,Summary!$B31,'Reconciliation Request'!$B$2:$B$755,Summary!$C31,'Reconciliation Request'!$H$2:$H$755,">0") -> 1 | P31: =N31-O31 -> 10 | Q31: =O31/N31 -> 0.090909091 | R31: =COUNTIFS('Reconciliation Request'!$A$2:$A$755,Summary!$B31,'Reconciliation Request'!$B$2:$B$755,Summary!$C31,'Reconciliation Request'!$K$2:$K$755,R$3) -> 2 | S31: =COUNTIFS('Reconciliation Request'!$A$2:$A$755,Summary!$B31,'Reconciliation Request'!$B$2:$B$755,Summary!$C31,'Reconciliation Request'!$K$2:$K$755,S$3) -> 7 | T31: =COUNTIFS('Reconciliation Request'!$A$2:$A$755,Summary!$B31,'Reconciliation Request'!$B$2:$B$755,Summary!$C31,'Reconciliation Request'!$K$2:$K$755,T$3) -> 2
