Workbook
Name DeltaList: 'Status key'!$C$29:$C$31
Name MigrationList: 'Status key'!$D$29:$D$35
Name SourceList: 'Status key'!$B$29:$B$30
Name StatusList: 'Status key'!$A$29:$A$36

Sheet Status summary
A1: Status by product and episode
A2: Every figure is a live formula over the Event stream steps tab, so this updates as the steps tab is filled in. Percentages are of the steps in that row. Status is progress through the work; source change and delta change describe the work itself and were filled in from the code.
D5: Status (column G) | M5: Source change (column I) | P5: Delta change (column K)
A6: Product | B6: Episode | C6: Steps | D6: Unchecked | E6: Triaged | F6: Blocked | G6: In progress | H6: In review | I6: Reconciled | J6: Done | K6: Not required | M6: Already ods | N6: Needs re-sourcing | P6: Windowed in query | Q6: Watermark sits upstream | R6: Needs a watermark
A7: Motor | B7: Acquisition | C7: =COUNTIFS('Event stream steps'!$C$2:$C$331,$A7,'Event stream steps'!$D$2:$D$331,$B7) -> 35 | D7: =IFERROR(COUNTIFS('Event stream steps'!$C$2:$C$331,$A7,'Event stream steps'!$D$2:$D$331,$B7,'Event stream steps'!$G$2:$G$331,D$6)/$C7,0) -> 1 | E7: =IFERROR(COUNTIFS('Event stream steps'!$C$2:$C$331,$A7,'Event stream steps'!$D$2:$D$331,$B7,'Event stream steps'!$G$2:$G$331,E$6)/$C7,0) -> 0 | F7: =IFERROR(COUNTIFS('Event stream steps'!$C$2:$C$331,$A7,'Event stream steps'!$D$2:$D$331,$B7,'Event stream steps'!$G$2:$G$331,F$6)/$C7,0) -> 0 | G7: =IFERROR(COUNTIFS('Event stream steps'!$C$2:$C$331,$A7,'Event stream steps'!$D$2:$D$331,$B7,'Event stream steps'!$G$2:$G$331,G$6)/$C7,0) -> 0 | H7: =IFERROR(COUNTIFS('Event stream steps'!$C$2:$C$331,$A7,'Event stream steps'!$D$2:$D$331,$B7,'Event stream steps'!$G$2:$G$331,H$6)/$C7,0) -> 0 | I7: =IFERROR(COUNTIFS('Event stream steps'!$C$2:$C$331,$A7,'Event stream steps'!$D$2:$D$331,$B7,'Event stream steps'!$G$2:$G$331,I$6)/$C7,0) -> 0 | J7: =IFERROR(COUNTIFS('Event stream steps'!$C$2:$C$331,$A7,'Event stream steps'!$D$2:$D$331,$B7,'Event stream steps'!$G$2:$G$331,J$6)/$C7,0) -> 0 | K7: =IFERROR(COUNTIFS('Event stream steps'!$C$2:$C$331,$A7,'Event stream steps'!$D$2:$D$331,$B7,'Event stream steps'!$G$2:$G$331,K$6)/$C7,0) -> 0 | M7: =IFERROR(COUNTIFS('Event stream steps'!$C$2:$C$331,$A7,'Event stream steps'!$D$2:$D$331,$B7,'Event stream steps'!$I$2:$I$331,M$6)/$C7,0) -> 0 | N7: =IFERROR(COUNTIFS('Event stream steps'!$C$2:$C$331,$A7,'Event stream steps'!$D$2:$D$331,$B7,'Event stream steps'!$I$2:$I$331,N$6)/$C7,0) -> 1 | P7: =IFERROR(COUNTIFS('Event stream steps'!$C$2:$C$331,$A7,'Event stream steps'!$D$2:$D$331,$B7,'Event stream steps'!$K$2:$K$331,P$6)/$C7,0) -> 0.71428571 | Q7: =IFERROR(COUNTIFS('Event stream steps'!$C$2:$C$331,$A7,'Event stream steps'!$D$2:$D$331,$B7,'Event stream steps'!$K$2:$K$331,Q$6)/$C7,0) -> 0.28571429 | R7: =IFERROR(COUNTIFS('Event stream steps'!$C$2:$C$331,$A7,'Event stream steps'!$D$2:$D$331,$B7,'Event stream steps'!$K$2:$K$331,R$6)/$C7,0) -> 0
A8: Motor | B8: Renewal | C8: =COUNTIFS('Event stream steps'!$C$2:$C$331,$A8,'Event stream steps'!$D$2:$D$331,$B8) -> 56 | D8: =IFERROR(COUNTIFS('Event stream steps'!$C$2:$C$331,$A8,'Event stream steps'!$D$2:$D$331,$B8,'Event stream steps'!$G$2:$G$331,D$6)/$C8,0) -> 1 | E8: =IFERROR(COUNTIFS('Event stream steps'!$C$2:$C$331,$A8,'Event stream steps'!$D$2:$D$331,$B8,'Event stream steps'!$G$2:$G$331,E$6)/$C8,0) -> 0 | F8: =IFERROR(COUNTIFS('Event stream steps'!$C$2:$C$331,$A8,'Event stream steps'!$D$2:$D$331,$B8,'Event stream steps'!$G$2:$G$331,F$6)/$C8,0) -> 0 | G8: =IFERROR(COUNTIFS('Event stream steps'!$C$2:$C$331,$A8,'Event stream steps'!$D$2:$D$331,$B8,'Event stream steps'!$G$2:$G$331,G$6)/$C8,0) -> 0 | H8: =IFERROR(COUNTIFS('Event stream steps'!$C$2:$C$331,$A8,'Event stream steps'!$D$2:$D$331,$B8,'Event stream steps'!$G$2:$G$331,H$6)/$C8,0) -> 0 | I8: =IFERROR(COUNTIFS('Event stream steps'!$C$2:$C$331,$A8,'Event stream steps'!$D$2:$D$331,$B8,'Event stream steps'!$G$2:$G$331,I$6)/$C8,0) -> 0 | J8: =IFERROR(COUNTIFS('Event stream steps'!$C$2:$C$331,$A8,'Event stream steps'!$D$2:$D$331,$B8,'Event stream steps'!$G$2:$G$331,J$6)/$C8,0) -> 0 | K8: =IFERROR(COUNTIFS('Event stream steps'!$C$2:$C$331,$A8,'Event stream steps'!$D$2:$D$331,$B8,'Event stream steps'!$G$2:$G$331,K$6)/$C8,0) -> 0 | M8: =IFERROR(COUNTIFS('Event stream steps'!$C$2:$C$331,$A8,'Event stream steps'!$D$2:$D$331,$B8,'Event stream steps'!$I$2:$I$331,M$6)/$C8,0) -> 0.035714286 | N8: =IFERROR(COUNTIFS('Event stream steps'!$C$2:$C$331,$A8,'Event stream steps'!$D$2:$D$331,$B8,'Event stream steps'!$I$2:$I$331,N$6)/$C8,0) -> 0.96428571 | P8: =IFERROR(COUNTIFS('Event stream steps'!$C$2:$C$331,$A8,'Event stream steps'!$D$2:$D$331,$B8,'Event stream steps'!$K$2:$K$331,P$6)/$C8,0) -> 0.53571429 | Q8: =IFERROR(COUNTIFS('Event stream steps'!$C$2:$C$331,$A8,'Event stream steps'!$D$2:$D$331,$B8,'Event stream steps'!$K$2:$K$331,Q$6)/$C8,0) -> 0.46428571 | R8: =IFERROR(COUNTIFS('Event stream steps'!$C$2:$C$331,$A8,'Event stream steps'!$D$2:$D$331,$B8,'Event stream steps'!$K$2:$K$331,R$6)/$C8,0) -> 0
A9: Motor | B9: MTA | C9: =COUNTIFS('Event stream steps'!$C$2:$C$331,$A9,'Event stream steps'!$D$2:$D$331,$B9) -> 16 | D9: =IFERROR(COUNTIFS('Event stream steps'!$C$2:$C$331,$A9,'Event stream steps'!$D$2:$D$331,$B9,'Event stream steps'!$G$2:$G$331,D$6)/$C9,0) -> 1 | E9: =IFERROR(COUNTIFS('Event stream steps'!$C$2:$C$331,$A9,'Event stream steps'!$D$2:$D$331,$B9,'Event stream steps'!$G$2:$G$331,E$6)/$C9,0) -> 0 | F9: =IFERROR(COUNTIFS('Event stream steps'!$C$2:$C$331,$A9,'Event stream steps'!$D$2:$D$331,$B9,'Event stream steps'!$G$2:$G$331,F$6)/$C9,0) -> 0 | G9: =IFERROR(COUNTIFS('Event stream steps'!$C$2:$C$331,$A9,'Event stream steps'!$D$2:$D$331,$B9,'Event stream steps'!$G$2:$G$331,G$6)/$C9,0) -> 0 | H9: =IFERROR(COUNTIFS('Event stream steps'!$C$2:$C$331,$A9,'Event stream steps'!$D$2:$D$331,$B9,'Event stream steps'!$G$2:$G$331,H$6)/$C9,0) -> 0 | I9: =IFERROR(COUNTIFS('Event stream steps'!$C$2:$C$331,$A9,'Event stream steps'!$D$2:$D$331,$B9,'Event stream steps'!$G$2:$G$331,I$6)/$C9,0) -> 0 | J9: =IFERROR(COUNTIFS('Event stream steps'!$C$2:$C$331,$A9,'Event stream steps'!$D$2:$D$331,$B9,'Event stream steps'!$G$2:$G$331,J$6)/$C9,0) -> 0 | K9: =IFERROR(COUNTIFS('Event stream steps'!$C$2:$C$331,$A9,'Event stream steps'!$D$2:$D$331,$B9,'Event stream steps'!$G$2:$G$331,K$6)/$C9,0) -> 0 | M9: =IFERROR(COUNTIFS('Event stream steps'!$C$2:$C$331,$A9,'Event stream steps'!$D$2:$D$331,$B9,'Event stream steps'!$I$2:$I$331,M$6)/$C9,0) -> 0 | N9: =IFERROR(COUNTIFS('Event stream steps'!$C$2:$C$331,$A9,'Event stream steps'!$D$2:$D$331,$B9,'Event stream steps'!$I$2:$I$331,N$6)/$C9,0) -> 1 | P9: =IFERROR(COUNTIFS('Event stream steps'!$C$2:$C$331,$A9,'Event stream steps'!$D$2:$D$331,$B9,'Event stream steps'!$K$2:$K$331,P$6)/$C9,0) -> 0.4375 | Q9: =IFERROR(COUNTIFS('Event stream steps'!$C$2:$C$331,$A9,'Event stream steps'!$D$2:$D$331,$B9,'Event stream steps'!$K$2:$K$331,Q$6)/$C9,0) -> 0.5625 | R9: =IFERROR(COUNTIFS('Event stream steps'!$C$2:$C$331,$A9,'Event stream steps'!$D$2:$D$331,$B9,'Event stream steps'!$K$2:$K$331,R$6)/$C9,0) -> 0
A10: Motor | B10: Cancellation | C10: =COUNTIFS('Event stream steps'!$C$2:$C$331,$A10,'Event stream steps'!$D$2:$D$331,$B10) -> 7 | D10: =IFERROR(COUNTIFS('Event stream steps'!$C$2:$C$331,$A10,'Event stream steps'!$D$2:$D$331,$B10,'Event stream steps'!$G$2:$G$331,D$6)/$C10,0) -> 1 | E10: =IFERROR(COUNTIFS('Event stream steps'!$C$2:$C$331,$A10,'Event stream steps'!$D$2:$D$331,$B10,'Event stream steps'!$G$2:$G$331,E$6)/$C10,0) -> 0 | F10: =IFERROR(COUNTIFS('Event stream steps'!$C$2:$C$331,$A10,'Event stream steps'!$D$2:$D$331,$B10,'Event stream steps'!$G$2:$G$331,F$6)/$C10,0) -> 0 | G10: =IFERROR(COUNTIFS('Event stream steps'!$C$2:$C$331,$A10,'Event stream steps'!$D$2:$D$331,$B10,'Event stream steps'!$G$2:$G$331,G$6)/$C10,0) -> 0 | H10: =IFERROR(COUNTIFS('Event stream steps'!$C$2:$C$331,$A10,'Event stream steps'!$D$2:$D$331,$B10,'Event stream steps'!$G$2:$G$331,H$6)/$C10,0) -> 0 | I10: =IFERROR(COUNTIFS('Event stream steps'!$C$2:$C$331,$A10,'Event stream steps'!$D$2:$D$331,$B10,'Event stream steps'!$G$2:$G$331,I$6)/$C10,0) -> 0 | J10: =IFERROR(COUNTIFS('Event stream steps'!$C$2:$C$331,$A10,'Event stream steps'!$D$2:$D$331,$B10,'Event stream steps'!$G$2:$G$331,J$6)/$C10,0) -> 0 | K10: =IFERROR(COUNTIFS('Event stream steps'!$C$2:$C$331,$A10,'Event stream steps'!$D$2:$D$331,$B10,'Event stream steps'!$G$2:$G$331,K$6)/$C10,0) -> 0 | M10: =IFERROR(COUNTIFS('Event stream steps'!$C$2:$C$331,$A10,'Event stream steps'!$D$2:$D$331,$B10,'Event stream steps'!$I$2:$I$331,M$6)/$C10,0) -> 0.14285714 | N10: =IFERROR(COUNTIFS('Event stream steps'!$C$2:$C$331,$A10,'Event stream steps'!$D$2:$D$331,$B10,'Event stream steps'!$I$2:$I$331,N$6)/$C10,0) -> 0.85714286 | P10: =IFERROR(COUNTIFS('Event stream steps'!$C$2:$C$331,$A10,'Event stream steps'!$D$2:$D$331,$B10,'Event stream steps'!$K$2:$K$331,P$6)/$C10,0) -> 1 | Q10: =IFERROR(COUNTIFS('Event stream steps'!$C$2:$C$331,$A10,'Event stream steps'!$D$2:$D$331,$B10,'Event stream steps'!$K$2:$K$331,Q$6)/$C10,0) -> 0 | R10: =IFERROR(COUNTIFS('Event stream steps'!$C$2:$C$331,$A10,'Event stream steps'!$D$2:$D$331,$B10,'Event stream steps'!$K$2:$K$331,R$6)/$C10,0) -> 0
A11: Motor | B11: Arrears | C11: =COUNTIFS('Event stream steps'!$C$2:$C$331,$A11,'Event stream steps'!$D$2:$D$331,$B11) -> 5 | D11: =IFERROR(COUNTIFS('Event stream steps'!$C$2:$C$331,$A11,'Event stream steps'!$D$2:$D$331,$B11,'Event stream steps'!$G$2:$G$331,D$6)/$C11,0) -> 1 | E11: =IFERROR(COUNTIFS('Event stream steps'!$C$2:$C$331,$A11,'Event stream steps'!$D$2:$D$331,$B11,'Event stream steps'!$G$2:$G$331,E$6)/$C11,0) -> 0 | F11: =IFERROR(COUNTIFS('Event stream steps'!$C$2:$C$331,$A11,'Event stream steps'!$D$2:$D$331,$B11,'Event stream steps'!$G$2:$G$331,F$6)/$C11,0) -> 0 | G11: =IFERROR(COUNTIFS('Event stream steps'!$C$2:$C$331,$A11,'Event stream steps'!$D$2:$D$331,$B11,'Event stream steps'!$G$2:$G$331,G$6)/$C11,0) -> 0 | H11: =IFERROR(COUNTIFS('Event stream steps'!$C$2:$C$331,$A11,'Event stream steps'!$D$2:$D$331,$B11,'Event stream steps'!$G$2:$G$331,H$6)/$C11,0) -> 0 | I11: =IFERROR(COUNTIFS('Event stream steps'!$C$2:$C$331,$A11,'Event stream steps'!$D$2:$D$331,$B11,'Event stream steps'!$G$2:$G$331,I$6)/$C11,0) -> 0 | J11: =IFERROR(COUNTIFS('Event stream steps'!$C$2:$C$331,$A11,'Event stream steps'!$D$2:$D$331,$B11,'Event stream steps'!$G$2:$G$331,J$6)/$C11,0) -> 0 | K11: =IFERROR(COUNTIFS('Event stream steps'!$C$2:$C$331,$A11,'Event stream steps'!$D$2:$D$331,$B11,'Event stream steps'!$G$2:$G$331,K$6)/$C11,0) -> 0 | M11: =IFERROR(COUNTIFS('Event stream steps'!$C$2:$C$331,$A11,'Event stream steps'!$D$2:$D$331,$B11,'Event stream steps'!$I$2:$I$331,M$6)/$C11,0) -> 0 | N11: =IFERROR(COUNTIFS('Event stream steps'!$C$2:$C$331,$A11,'Event stream steps'!$D$2:$D$331,$B11,'Event stream steps'!$I$2:$I$331,N$6)/$C11,0) -> 1 | P11: =IFERROR(COUNTIFS('Event stream steps'!$C$2:$C$331,$A11,'Event stream steps'!$D$2:$D$331,$B11,'Event stream steps'!$K$2:$K$331,P$6)/$C11,0) -> 1 | Q11: =IFERROR(COUNTIFS('Event stream steps'!$C$2:$C$331,$A11,'Event stream steps'!$D$2:$D$331,$B11,'Event stream steps'!$K$2:$K$331,Q$6)/$C11,0) -> 0 | R11: =IFERROR(COUNTIFS('Event stream steps'!$C$2:$C$331,$A11,'Event stream steps'!$D$2:$D$331,$B11,'Event stream steps'!$K$2:$K$331,R$6)/$C11,0) -> 0
A12: Motor | B12: Claims | C12: =COUNTIFS('Event stream steps'!$C$2:$C$331,$A12,'Event stream steps'!$D$2:$D$331,$B12) -> 1 | D12: =IFERROR(COUNTIFS('Event stream steps'!$C$2:$C$331,$A12,'Event stream steps'!$D$2:$D$331,$B12,'Event stream steps'!$G$2:$G$331,D$6)/$C12,0) -> 1 | E12: =IFERROR(COUNTIFS('Event stream steps'!$C$2:$C$331,$A12,'Event stream steps'!$D$2:$D$331,$B12,'Event stream steps'!$G$2:$G$331,E$6)/$C12,0) -> 0 | F12: =IFERROR(COUNTIFS('Event stream steps'!$C$2:$C$331,$A12,'Event stream steps'!$D$2:$D$331,$B12,'Event stream steps'!$G$2:$G$331,F$6)/$C12,0) -> 0 | G12: =IFERROR(COUNTIFS('Event stream steps'!$C$2:$C$331,$A12,'Event stream steps'!$D$2:$D$331,$B12,'Event stream steps'!$G$2:$G$331,G$6)/$C12,0) -> 0 | H12: =IFERROR(COUNTIFS('Event stream steps'!$C$2:$C$331,$A12,'Event stream steps'!$D$2:$D$331,$B12,'Event stream steps'!$G$2:$G$331,H$6)/$C12,0) -> 0 | I12: =IFERROR(COUNTIFS('Event stream steps'!$C$2:$C$331,$A12,'Event stream steps'!$D$2:$D$331,$B12,'Event stream steps'!$G$2:$G$331,I$6)/$C12,0) -> 0 | J12: =IFERROR(COUNTIFS('Event stream steps'!$C$2:$C$331,$A12,'Event stream steps'!$D$2:$D$331,$B12,'Event stream steps'!$G$2:$G$331,J$6)/$C12,0) -> 0 | K12: =IFERROR(COUNTIFS('Event stream steps'!$C$2:$C$331,$A12,'Event stream steps'!$D$2:$D$331,$B12,'Event stream steps'!$G$2:$G$331,K$6)/$C12,0) -> 0 | M12: =IFERROR(COUNTIFS('Event stream steps'!$C$2:$C$331,$A12,'Event stream steps'!$D$2:$D$331,$B12,'Event stream steps'!$I$2:$I$331,M$6)/$C12,0) -> 0 | N12: =IFERROR(COUNTIFS('Event stream steps'!$C$2:$C$331,$A12,'Event stream steps'!$D$2:$D$331,$B12,'Event stream steps'!$I$2:$I$331,N$6)/$C12,0) -> 1 | P12: =IFERROR(COUNTIFS('Event stream steps'!$C$2:$C$331,$A12,'Event stream steps'!$D$2:$D$331,$B12,'Event stream steps'!$K$2:$K$331,P$6)/$C12,0) -> 0 | Q12: =IFERROR(COUNTIFS('Event stream steps'!$C$2:$C$331,$A12,'Event stream steps'!$D$2:$D$331,$B12,'Event stream steps'!$K$2:$K$331,Q$6)/$C12,0) -> 1 | R12: =IFERROR(COUNTIFS('Event stream steps'!$C$2:$C$331,$A12,'Event stream steps'!$D$2:$D$331,$B12,'Event stream steps'!$K$2:$K$331,R$6)/$C12,0) -> 0
A13: Motor | B13: Doc Request | C13: =COUNTIFS('Event stream steps'!$C$2:$C$331,$A13,'Event stream steps'!$D$2:$D$331,$B13) -> 6 | D13: =IFERROR(COUNTIFS('Event stream steps'!$C$2:$C$331,$A13,'Event stream steps'!$D$2:$D$331,$B13,'Event stream steps'!$G$2:$G$331,D$6)/$C13,0) -> 1 | E13: =IFERROR(COUNTIFS('Event stream steps'!$C$2:$C$331,$A13,'Event stream steps'!$D$2:$D$331,$B13,'Event stream steps'!$G$2:$G$331,E$6)/$C13,0) -> 0 | F13: =IFERROR(COUNTIFS('Event stream steps'!$C$2:$C$331,$A13,'Event stream steps'!$D$2:$D$331,$B13,'Event stream steps'!$G$2:$G$331,F$6)/$C13,0) -> 0 | G13: =IFERROR(COUNTIFS('Event stream steps'!$C$2:$C$331,$A13,'Event stream steps'!$D$2:$D$331,$B13,'Event stream steps'!$G$2:$G$331,G$6)/$C13,0) -> 0 | H13: =IFERROR(COUNTIFS('Event stream steps'!$C$2:$C$331,$A13,'Event stream steps'!$D$2:$D$331,$B13,'Event stream steps'!$G$2:$G$331,H$6)/$C13,0) -> 0 | I13: =IFERROR(COUNTIFS('Event stream steps'!$C$2:$C$331,$A13,'Event stream steps'!$D$2:$D$331,$B13,'Event stream steps'!$G$2:$G$331,I$6)/$C13,0) -> 0 | J13: =IFERROR(COUNTIFS('Event stream steps'!$C$2:$C$331,$A13,'Event stream steps'!$D$2:$D$331,$B13,'Event stream steps'!$G$2:$G$331,J$6)/$C13,0) -> 0 | K13: =IFERROR(COUNTIFS('Event stream steps'!$C$2:$C$331,$A13,'Event stream steps'!$D$2:$D$331,$B13,'Event stream steps'!$G$2:$G$331,K$6)/$C13,0) -> 0 | M13: =IFERROR(COUNTIFS('Event stream steps'!$C$2:$C$331,$A13,'Event stream steps'!$D$2:$D$331,$B13,'Event stream steps'!$I$2:$I$331,M$6)/$C13,0) -> 0 | N13: =IFERROR(COUNTIFS('Event stream steps'!$C$2:$C$331,$A13,'Event stream steps'!$D$2:$D$331,$B13,'Event stream steps'!$I$2:$I$331,N$6)/$C13,0) -> 1 | P13: =IFERROR(COUNTIFS('Event stream steps'!$C$2:$C$331,$A13,'Event stream steps'!$D$2:$D$331,$B13,'Event stream steps'!$K$2:$K$331,P$6)/$C13,0) -> 0 | Q13: =IFERROR(COUNTIFS('Event stream steps'!$C$2:$C$331,$A13,'Event stream steps'!$D$2:$D$331,$B13,'Event stream steps'!$K$2:$K$331,Q$6)/$C13,0) -> 1 | R13: =IFERROR(COUNTIFS('Event stream steps'!$C$2:$C$331,$A13,'Event stream steps'!$D$2:$D$331,$B13,'Event stream steps'!$K$2:$K$331,R$6)/$C13,0) -> 0
A14: Motor | B14: All episodes | C14: =COUNTIFS('Event stream steps'!$C$2:$C$331,$A14) -> 126 | D14: =IFERROR(COUNTIFS('Event stream steps'!$C$2:$C$331,$A14,'Event stream steps'!$G$2:$G$331,D$6)/$C14,0) -> 1 | E14: =IFERROR(COUNTIFS('Event stream steps'!$C$2:$C$331,$A14,'Event stream steps'!$G$2:$G$331,E$6)/$C14,0) -> 0 | F14: =IFERROR(COUNTIFS('Event stream steps'!$C$2:$C$331,$A14,'Event stream steps'!$G$2:$G$331,F$6)/$C14,0) -> 0 | G14: =IFERROR(COUNTIFS('Event stream steps'!$C$2:$C$331,$A14,'Event stream steps'!$G$2:$G$331,G$6)/$C14,0) -> 0 | H14: =IFERROR(COUNTIFS('Event stream steps'!$C$2:$C$331,$A14,'Event stream steps'!$G$2:$G$331,H$6)/$C14,0) -> 0 | I14: =IFERROR(COUNTIFS('Event stream steps'!$C$2:$C$331,$A14,'Event stream steps'!$G$2:$G$331,I$6)/$C14,0) -> 0 | J14: =IFERROR(COUNTIFS('Event stream steps'!$C$2:$C$331,$A14,'Event stream steps'!$G$2:$G$331,J$6)/$C14,0) -> 0 | K14: =IFERROR(COUNTIFS('Event stream steps'!$C$2:$C$331,$A14,'Event stream steps'!$G$2:$G$331,K$6)/$C14,0) -> 0 | M14: =IFERROR(COUNTIFS('Event stream steps'!$C$2:$C$331,$A14,'Event stream steps'!$I$2:$I$331,M$6)/$C14,0) -> 0.023809524 | N14: =IFERROR(COUNTIFS('Event stream steps'!$C$2:$C$331,$A14,'Event stream steps'!$I$2:$I$331,N$6)/$C14,0) -> 0.97619048 | P14: =IFERROR(COUNTIFS('Event stream steps'!$C$2:$C$331,$A14,'Event stream steps'!$K$2:$K$331,P$6)/$C14,0) -> 0.58730159 | Q14: =IFERROR(COUNTIFS('Event stream steps'!$C$2:$C$331,$A14,'Event stream steps'!$K$2:$K$331,Q$6)/$C14,0) -> 0.41269841 | R14: =IFERROR(COUNTIFS('Event stream steps'!$C$2:$C$331,$A14,'Event stream steps'!$K$2:$K$331,R$6)/$C14,0) -> 0
A15: Home | B15: Acquisition | C15: =COUNTIFS('Event stream steps'!$C$2:$C$331,$A15,'Event stream steps'!$D$2:$D$331,$B15) -> 32 | D15: =IFERROR(COUNTIFS('Event stream steps'!$C$2:$C$331,$A15,'Event stream steps'!$D$2:$D$331,$B15,'Event stream steps'!$G$2:$G$331,D$6)/$C15,0) -> 1 | E15: =IFERROR(COUNTIFS('Event stream steps'!$C$2:$C$331,$A15,'Event stream steps'!$D$2:$D$331,$B15,'Event stream steps'!$G$2:$G$331,E$6)/$C15,0) -> 0 | F15: =IFERROR(COUNTIFS('Event stream steps'!$C$2:$C$331,$A15,'Event stream steps'!$D$2:$D$331,$B15,'Event stream steps'!$G$2:$G$331,F$6)/$C15,0) -> 0 | G15: =IFERROR(COUNTIFS('Event stream steps'!$C$2:$C$331,$A15,'Event stream steps'!$D$2:$D$331,$B15,'Event stream steps'!$G$2:$G$331,G$6)/$C15,0) -> 0 | H15: =IFERROR(COUNTIFS('Event stream steps'!$C$2:$C$331,$A15,'Event stream steps'!$D$2:$D$331,$B15,'Event stream steps'!$G$2:$G$331,H$6)/$C15,0) -> 0 | I15: =IFERROR(COUNTIFS('Event stream steps'!$C$2:$C$331,$A15,'Event stream steps'!$D$2:$D$331,$B15,'Event stream steps'!$G$2:$G$331,I$6)/$C15,0) -> 0 | J15: =IFERROR(COUNTIFS('Event stream steps'!$C$2:$C$331,$A15,'Event stream steps'!$D$2:$D$331,$B15,'Event stream steps'!$G$2:$G$331,J$6)/$C15,0) -> 0 | K15: =IFERROR(COUNTIFS('Event stream steps'!$C$2:$C$331,$A15,'Event stream steps'!$D$2:$D$331,$B15,'Event stream steps'!$G$2:$G$331,K$6)/$C15,0) -> 0 | M15: =IFERROR(COUNTIFS('Event stream steps'!$C$2:$C$331,$A15,'Event stream steps'!$D$2:$D$331,$B15,'Event stream steps'!$I$2:$I$331,M$6)/$C15,0) -> 0 | N15: =IFERROR(COUNTIFS('Event stream steps'!$C$2:$C$331,$A15,'Event stream steps'!$D$2:$D$331,$B15,'Event stream steps'!$I$2:$I$331,N$6)/$C15,0) -> 1 | P15: =IFERROR(COUNTIFS('Event stream steps'!$C$2:$C$331,$A15,'Event stream steps'!$D$2:$D$331,$B15,'Event stream steps'!$K$2:$K$331,P$6)/$C15,0) -> 0.78125 | Q15: =IFERROR(COUNTIFS('Event stream steps'!$C$2:$C$331,$A15,'Event stream steps'!$D$2:$D$331,$B15,'Event stream steps'!$K$2:$K$331,Q$6)/$C15,0) -> 0.21875 | R15: =IFERROR(COUNTIFS('Event stream steps'!$C$2:$C$331,$A15,'Event stream steps'!$D$2:$D$331,$B15,'Event stream steps'!$K$2:$K$331,R$6)/$C15,0) -> 0
A16: Home | B16: Renewal | C16: =COUNTIFS('Event stream steps'!$C$2:$C$331,$A16,'Event stream steps'!$D$2:$D$331,$B16) -> 45 | D16: =IFERROR(COUNTIFS('Event stream steps'!$C$2:$C$331,$A16,'Event stream steps'!$D$2:$D$331,$B16,'Event stream steps'!$G$2:$G$331,D$6)/$C16,0) -> 1 | E16: =IFERROR(COUNTIFS('Event stream steps'!$C$2:$C$331,$A16,'Event stream steps'!$D$2:$D$331,$B16,'Event stream steps'!$G$2:$G$331,E$6)/$C16,0) -> 0 | F16: =IFERROR(COUNTIFS('Event stream steps'!$C$2:$C$331,$A16,'Event stream steps'!$D$2:$D$331,$B16,'Event stream steps'!$G$2:$G$331,F$6)/$C16,0) -> 0 | G16: =IFERROR(COUNTIFS('Event stream steps'!$C$2:$C$331,$A16,'Event stream steps'!$D$2:$D$331,$B16,'Event stream steps'!$G$2:$G$331,G$6)/$C16,0) -> 0 | H16: =IFERROR(COUNTIFS('Event stream steps'!$C$2:$C$331,$A16,'Event stream steps'!$D$2:$D$331,$B16,'Event stream steps'!$G$2:$G$331,H$6)/$C16,0) -> 0 | I16: =IFERROR(COUNTIFS('Event stream steps'!$C$2:$C$331,$A16,'Event stream steps'!$D$2:$D$331,$B16,'Event stream steps'!$G$2:$G$331,I$6)/$C16,0) -> 0 | J16: =IFERROR(COUNTIFS('Event stream steps'!$C$2:$C$331,$A16,'Event stream steps'!$D$2:$D$331,$B16,'Event stream steps'!$G$2:$G$331,J$6)/$C16,0) -> 0 | K16: =IFERROR(COUNTIFS('Event stream steps'!$C$2:$C$331,$A16,'Event stream steps'!$D$2:$D$331,$B16,'Event stream steps'!$G$2:$G$331,K$6)/$C16,0) -> 0 | M16: =IFERROR(COUNTIFS('Event stream steps'!$C$2:$C$331,$A16,'Event stream steps'!$D$2:$D$331,$B16,'Event stream steps'!$I$2:$I$331,M$6)/$C16,0) -> 0 | N16: =IFERROR(COUNTIFS('Event stream steps'!$C$2:$C$331,$A16,'Event stream steps'!$D$2:$D$331,$B16,'Event stream steps'!$I$2:$I$331,N$6)/$C16,0) -> 1 | P16: =IFERROR(COUNTIFS('Event stream steps'!$C$2:$C$331,$A16,'Event stream steps'!$D$2:$D$331,$B16,'Event stream steps'!$K$2:$K$331,P$6)/$C16,0) -> 0.57777778 | Q16: =IFERROR(COUNTIFS('Event stream steps'!$C$2:$C$331,$A16,'Event stream steps'!$D$2:$D$331,$B16,'Event stream steps'!$K$2:$K$331,Q$6)/$C16,0) -> 0.42222222 | R16: =IFERROR(COUNTIFS('Event stream steps'!$C$2:$C$331,$A16,'Event stream steps'!$D$2:$D$331,$B16,'Event stream steps'!$K$2:$K$331,R$6)/$C16,0) -> 0
A17: Home | B17: MTA | C17: =COUNTIFS('Event stream steps'!$C$2:$C$331,$A17,'Event stream steps'!$D$2:$D$331,$B17) -> 18 | D17: =IFERROR(COUNTIFS('Event stream steps'!$C$2:$C$331,$A17,'Event stream steps'!$D$2:$D$331,$B17,'Event stream steps'!$G$2:$G$331,D$6)/$C17,0) -> 1 | E17: =IFERROR(COUNTIFS('Event stream steps'!$C$2:$C$331,$A17,'Event stream steps'!$D$2:$D$331,$B17,'Event stream steps'!$G$2:$G$331,E$6)/$C17,0) -> 0 | F17: =IFERROR(COUNTIFS('Event stream steps'!$C$2:$C$331,$A17,'Event stream steps'!$D$2:$D$331,$B17,'Event stream steps'!$G$2:$G$331,F$6)/$C17,0) -> 0 | G17: =IFERROR(COUNTIFS('Event stream steps'!$C$2:$C$331,$A17,'Event stream steps'!$D$2:$D$331,$B17,'Event stream steps'!$G$2:$G$331,G$6)/$C17,0) -> 0 | H17: =IFERROR(COUNTIFS('Event stream steps'!$C$2:$C$331,$A17,'Event stream steps'!$D$2:$D$331,$B17,'Event stream steps'!$G$2:$G$331,H$6)/$C17,0) -> 0 | I17: =IFERROR(COUNTIFS('Event stream steps'!$C$2:$C$331,$A17,'Event stream steps'!$D$2:$D$331,$B17,'Event stream steps'!$G$2:$G$331,I$6)/$C17,0) -> 0 | J17: =IFERROR(COUNTIFS('Event stream steps'!$C$2:$C$331,$A17,'Event stream steps'!$D$2:$D$331,$B17,'Event stream steps'!$G$2:$G$331,J$6)/$C17,0) -> 0 | K17: =IFERROR(COUNTIFS('Event stream steps'!$C$2:$C$331,$A17,'Event stream steps'!$D$2:$D$331,$B17,'Event stream steps'!$G$2:$G$331,K$6)/$C17,0) -> 0 | M17: =IFERROR(COUNTIFS('Event stream steps'!$C$2:$C$331,$A17,'Event stream steps'!$D$2:$D$331,$B17,'Event stream steps'!$I$2:$I$331,M$6)/$C17,0) -> 0 | N17: =IFERROR(COUNTIFS('Event stream steps'!$C$2:$C$331,$A17,'Event stream steps'!$D$2:$D$331,$B17,'Event stream steps'!$I$2:$I$331,N$6)/$C17,0) -> 1 | P17: =IFERROR(COUNTIFS('Event stream steps'!$C$2:$C$331,$A17,'Event stream steps'!$D$2:$D$331,$B17,'Event stream steps'!$K$2:$K$331,P$6)/$C17,0) -> 0.61111111 | Q17: =IFERROR(COUNTIFS('Event stream steps'!$C$2:$C$331,$A17,'Event stream steps'!$D$2:$D$331,$B17,'Event stream steps'!$K$2:$K$331,Q$6)/$C17,0) -> 0.38888889 | R17: =IFERROR(COUNTIFS('Event stream steps'!$C$2:$C$331,$A17,'Event stream steps'!$D$2:$D$331,$B17,'Event stream steps'!$K$2:$K$331,R$6)/$C17,0) -> 0
A18: Home | B18: Cancellation | C18: =COUNTIFS('Event stream steps'!$C$2:$C$331,$A18,'Event stream steps'!$D$2:$D$331,$B18) -> 7 | D18: =IFERROR(COUNTIFS('Event stream steps'!$C$2:$C$331,$A18,'Event stream steps'!$D$2:$D$331,$B18,'Event stream steps'!$G$2:$G$331,D$6)/$C18,0) -> 1 | E18: =IFERROR(COUNTIFS('Event stream steps'!$C$2:$C$331,$A18,'Event stream steps'!$D$2:$D$331,$B18,'Event stream steps'!$G$2:$G$331,E$6)/$C18,0) -> 0 | F18: =IFERROR(COUNTIFS('Event stream steps'!$C$2:$C$331,$A18,'Event stream steps'!$D$2:$D$331,$B18,'Event stream steps'!$G$2:$G$331,F$6)/$C18,0) -> 0 | G18: =IFERROR(COUNTIFS('Event stream steps'!$C$2:$C$331,$A18,'Event stream steps'!$D$2:$D$331,$B18,'Event stream steps'!$G$2:$G$331,G$6)/$C18,0) -> 0 | H18: =IFERROR(COUNTIFS('Event stream steps'!$C$2:$C$331,$A18,'Event stream steps'!$D$2:$D$331,$B18,'Event stream steps'!$G$2:$G$331,H$6)/$C18,0) -> 0 | I18: =IFERROR(COUNTIFS('Event stream steps'!$C$2:$C$331,$A18,'Event stream steps'!$D$2:$D$331,$B18,'Event stream steps'!$G$2:$G$331,I$6)/$C18,0) -> 0 | J18: =IFERROR(COUNTIFS('Event stream steps'!$C$2:$C$331,$A18,'Event stream steps'!$D$2:$D$331,$B18,'Event stream steps'!$G$2:$G$331,J$6)/$C18,0) -> 0 | K18: =IFERROR(COUNTIFS('Event stream steps'!$C$2:$C$331,$A18,'Event stream steps'!$D$2:$D$331,$B18,'Event stream steps'!$G$2:$G$331,K$6)/$C18,0) -> 0 | M18: =IFERROR(COUNTIFS('Event stream steps'!$C$2:$C$331,$A18,'Event stream steps'!$D$2:$D$331,$B18,'Event stream steps'!$I$2:$I$331,M$6)/$C18,0) -> 0.14285714 | N18: =IFERROR(COUNTIFS('Event stream steps'!$C$2:$C$331,$A18,'Event stream steps'!$D$2:$D$331,$B18,'Event stream steps'!$I$2:$I$331,N$6)/$C18,0) -> 0.85714286 | P18: =IFERROR(COUNTIFS('Event stream steps'!$C$2:$C$331,$A18,'Event stream steps'!$D$2:$D$331,$B18,'Event stream steps'!$K$2:$K$331,P$6)/$C18,0) -> 1 | Q18: =IFERROR(COUNTIFS('Event stream steps'!$C$2:$C$331,$A18,'Event stream steps'!$D$2:$D$331,$B18,'Event stream steps'!$K$2:$K$331,Q$6)/$C18,0) -> 0 | R18: =IFERROR(COUNTIFS('Event stream steps'!$C$2:$C$331,$A18,'Event stream steps'!$D$2:$D$331,$B18,'Event stream steps'!$K$2:$K$331,R$6)/$C18,0) -> 0
A19: Home | B19: Arrears | C19: =COUNTIFS('Event stream steps'!$C$2:$C$331,$A19,'Event stream steps'!$D$2:$D$331,$B19) -> 5 | D19: =IFERROR(COUNTIFS('Event stream steps'!$C$2:$C$331,$A19,'Event stream steps'!$D$2:$D$331,$B19,'Event stream steps'!$G$2:$G$331,D$6)/$C19,0) -> 1 | E19: =IFERROR(COUNTIFS('Event stream steps'!$C$2:$C$331,$A19,'Event stream steps'!$D$2:$D$331,$B19,'Event stream steps'!$G$2:$G$331,E$6)/$C19,0) -> 0 | F19: =IFERROR(COUNTIFS('Event stream steps'!$C$2:$C$331,$A19,'Event stream steps'!$D$2:$D$331,$B19,'Event stream steps'!$G$2:$G$331,F$6)/$C19,0) -> 0 | G19: =IFERROR(COUNTIFS('Event stream steps'!$C$2:$C$331,$A19,'Event stream steps'!$D$2:$D$331,$B19,'Event stream steps'!$G$2:$G$331,G$6)/$C19,0) -> 0 | H19: =IFERROR(COUNTIFS('Event stream steps'!$C$2:$C$331,$A19,'Event stream steps'!$D$2:$D$331,$B19,'Event stream steps'!$G$2:$G$331,H$6)/$C19,0) -> 0 | I19: =IFERROR(COUNTIFS('Event stream steps'!$C$2:$C$331,$A19,'Event stream steps'!$D$2:$D$331,$B19,'Event stream steps'!$G$2:$G$331,I$6)/$C19,0) -> 0 | J19: =IFERROR(COUNTIFS('Event stream steps'!$C$2:$C$331,$A19,'Event stream steps'!$D$2:$D$331,$B19,'Event stream steps'!$G$2:$G$331,J$6)/$C19,0) -> 0 | K19: =IFERROR(COUNTIFS('Event stream steps'!$C$2:$C$331,$A19,'Event stream steps'!$D$2:$D$331,$B19,'Event stream steps'!$G$2:$G$331,K$6)/$C19,0) -> 0 | M19: =IFERROR(COUNTIFS('Event stream steps'!$C$2:$C$331,$A19,'Event stream steps'!$D$2:$D$331,$B19,'Event stream steps'!$I$2:$I$331,M$6)/$C19,0) -> 0 | N19: =IFERROR(COUNTIFS('Event stream steps'!$C$2:$C$331,$A19,'Event stream steps'!$D$2:$D$331,$B19,'Event stream steps'!$I$2:$I$331,N$6)/$C19,0) -> 1 | P19: =IFERROR(COUNTIFS('Event stream steps'!$C$2:$C$331,$A19,'Event stream steps'!$D$2:$D$331,$B19,'Event stream steps'!$K$2:$K$331,P$6)/$C19,0) -> 1 | Q19: =IFERROR(COUNTIFS('Event stream steps'!$C$2:$C$331,$A19,'Event stream steps'!$D$2:$D$331,$B19,'Event stream steps'!$K$2:$K$331,Q$6)/$C19,0) -> 0 | R19: =IFERROR(COUNTIFS('Event stream steps'!$C$2:$C$331,$A19,'Event stream steps'!$D$2:$D$331,$B19,'Event stream steps'!$K$2:$K$331,R$6)/$C19,0) -> 0
A20: Home | B20: Claims | C20: =COUNTIFS('Event stream steps'!$C$2:$C$331,$A20,'Event stream steps'!$D$2:$D$331,$B20) -> 4 | D20: =IFERROR(COUNTIFS('Event stream steps'!$C$2:$C$331,$A20,'Event stream steps'!$D$2:$D$331,$B20,'Event stream steps'!$G$2:$G$331,D$6)/$C20,0) -> 1 | E20: =IFERROR(COUNTIFS('Event stream steps'!$C$2:$C$331,$A20,'Event stream steps'!$D$2:$D$331,$B20,'Event stream steps'!$G$2:$G$331,E$6)/$C20,0) -> 0 | F20: =IFERROR(COUNTIFS('Event stream steps'!$C$2:$C$331,$A20,'Event stream steps'!$D$2:$D$331,$B20,'Event stream steps'!$G$2:$G$331,F$6)/$C20,0) -> 0 | G20: =IFERROR(COUNTIFS('Event stream steps'!$C$2:$C$331,$A20,'Event stream steps'!$D$2:$D$331,$B20,'Event stream steps'!$G$2:$G$331,G$6)/$C20,0) -> 0 | H20: =IFERROR(COUNTIFS('Event stream steps'!$C$2:$C$331,$A20,'Event stream steps'!$D$2:$D$331,$B20,'Event stream steps'!$G$2:$G$331,H$6)/$C20,0) -> 0 | I20: =IFERROR(COUNTIFS('Event stream steps'!$C$2:$C$331,$A20,'Event stream steps'!$D$2:$D$331,$B20,'Event stream steps'!$G$2:$G$331,I$6)/$C20,0) -> 0 | J20: =IFERROR(COUNTIFS('Event stream steps'!$C$2:$C$331,$A20,'Event stream steps'!$D$2:$D$331,$B20,'Event stream steps'!$G$2:$G$331,J$6)/$C20,0) -> 0 | K20: =IFERROR(COUNTIFS('Event stream steps'!$C$2:$C$331,$A20,'Event stream steps'!$D$2:$D$331,$B20,'Event stream steps'!$G$2:$G$331,K$6)/$C20,0) -> 0 | M20: =IFERROR(COUNTIFS('Event stream steps'!$C$2:$C$331,$A20,'Event stream steps'!$D$2:$D$331,$B20,'Event stream steps'!$I$2:$I$331,M$6)/$C20,0) -> 0 | N20: =IFERROR(COUNTIFS('Event stream steps'!$C$2:$C$331,$A20,'Event stream steps'!$D$2:$D$331,$B20,'Event stream steps'!$I$2:$I$331,N$6)/$C20,0) -> 1 | P20: =IFERROR(COUNTIFS('Event stream steps'!$C$2:$C$331,$A20,'Event stream steps'!$D$2:$D$331,$B20,'Event stream steps'!$K$2:$K$331,P$6)/$C20,0) -> 0.75 | Q20: =IFERROR(COUNTIFS('Event stream steps'!$C$2:$C$331,$A20,'Event stream steps'!$D$2:$D$331,$B20,'Event stream steps'!$K$2:$K$331,Q$6)/$C20,0) -> 0.25 | R20: =IFERROR(COUNTIFS('Event stream steps'!$C$2:$C$331,$A20,'Event stream steps'!$D$2:$D$331,$B20,'Event stream steps'!$K$2:$K$331,R$6)/$C20,0) -> 0
A21: Home | B21: Doc Request | C21: =COUNTIFS('Event stream steps'!$C$2:$C$331,$A21,'Event stream steps'!$D$2:$D$331,$B21) -> 5 | D21: =IFERROR(COUNTIFS('Event stream steps'!$C$2:$C$331,$A21,'Event stream steps'!$D$2:$D$331,$B21,'Event stream steps'!$G$2:$G$331,D$6)/$C21,0) -> 1 | E21: =IFERROR(COUNTIFS('Event stream steps'!$C$2:$C$331,$A21,'Event stream steps'!$D$2:$D$331,$B21,'Event stream steps'!$G$2:$G$331,E$6)/$C21,0) -> 0 | F21: =IFERROR(COUNTIFS('Event stream steps'!$C$2:$C$331,$A21,'Event stream steps'!$D$2:$D$331,$B21,'Event stream steps'!$G$2:$G$331,F$6)/$C21,0) -> 0 | G21: =IFERROR(COUNTIFS('Event stream steps'!$C$2:$C$331,$A21,'Event stream steps'!$D$2:$D$331,$B21,'Event stream steps'!$G$2:$G$331,G$6)/$C21,0) -> 0 | H21: =IFERROR(COUNTIFS('Event stream steps'!$C$2:$C$331,$A21,'Event stream steps'!$D$2:$D$331,$B21,'Event stream steps'!$G$2:$G$331,H$6)/$C21,0) -> 0 | I21: =IFERROR(COUNTIFS('Event stream steps'!$C$2:$C$331,$A21,'Event stream steps'!$D$2:$D$331,$B21,'Event stream steps'!$G$2:$G$331,I$6)/$C21,0) -> 0 | J21: =IFERROR(COUNTIFS('Event stream steps'!$C$2:$C$331,$A21,'Event stream steps'!$D$2:$D$331,$B21,'Event stream steps'!$G$2:$G$331,J$6)/$C21,0) -> 0 | K21: =IFERROR(COUNTIFS('Event stream steps'!$C$2:$C$331,$A21,'Event stream steps'!$D$2:$D$331,$B21,'Event stream steps'!$G$2:$G$331,K$6)/$C21,0) -> 0 | M21: =IFERROR(COUNTIFS('Event stream steps'!$C$2:$C$331,$A21,'Event stream steps'!$D$2:$D$331,$B21,'Event stream steps'!$I$2:$I$331,M$6)/$C21,0) -> 0 | N21: =IFERROR(COUNTIFS('Event stream steps'!$C$2:$C$331,$A21,'Event stream steps'!$D$2:$D$331,$B21,'Event stream steps'!$I$2:$I$331,N$6)/$C21,0) -> 1 | P21: =IFERROR(COUNTIFS('Event stream steps'!$C$2:$C$331,$A21,'Event stream steps'!$D$2:$D$331,$B21,'Event stream steps'!$K$2:$K$331,P$6)/$C21,0) -> 0 | Q21: =IFERROR(COUNTIFS('Event stream steps'!$C$2:$C$331,$A21,'Event stream steps'!$D$2:$D$331,$B21,'Event stream steps'!$K$2:$K$331,Q$6)/$C21,0) -> 1 | R21: =IFERROR(COUNTIFS('Event stream steps'!$C$2:$C$331,$A21,'Event stream steps'!$D$2:$D$331,$B21,'Event stream steps'!$K$2:$K$331,R$6)/$C21,0) -> 0
A22: Home | B22: All episodes | C22: =COUNTIFS('Event stream steps'!$C$2:$C$331,$A22) -> 116 | D22: =IFERROR(COUNTIFS('Event stream steps'!$C$2:$C$331,$A22,'Event stream steps'!$G$2:$G$331,D$6)/$C22,0) -> 1 | E22: =IFERROR(COUNTIFS('Event stream steps'!$C$2:$C$331,$A22,'Event stream steps'!$G$2:$G$331,E$6)/$C22,0) -> 0 | F22: =IFERROR(COUNTIFS('Event stream steps'!$C$2:$C$331,$A22,'Event stream steps'!$G$2:$G$331,F$6)/$C22,0) -> 0 | G22: =IFERROR(COUNTIFS('Event stream steps'!$C$2:$C$331,$A22,'Event stream steps'!$G$2:$G$331,G$6)/$C22,0) -> 0 | H22: =IFERROR(COUNTIFS('Event stream steps'!$C$2:$C$331,$A22,'Event stream steps'!$G$2:$G$331,H$6)/$C22,0) -> 0 | I22: =IFERROR(COUNTIFS('Event stream steps'!$C$2:$C$331,$A22,'Event stream steps'!$G$2:$G$331,I$6)/$C22,0) -> 0 | J22: =IFERROR(COUNTIFS('Event stream steps'!$C$2:$C$331,$A22,'Event stream steps'!$G$2:$G$331,J$6)/$C22,0) -> 0 | K22: =IFERROR(COUNTIFS('Event stream steps'!$C$2:$C$331,$A22,'Event stream steps'!$G$2:$G$331,K$6)/$C22,0) -> 0 | M22: =IFERROR(COUNTIFS('Event stream steps'!$C$2:$C$331,$A22,'Event stream steps'!$I$2:$I$331,M$6)/$C22,0) -> 0.0086206897 | N22: =IFERROR(COUNTIFS('Event stream steps'!$C$2:$C$331,$A22,'Event stream steps'!$I$2:$I$331,N$6)/$C22,0) -> 0.99137931 | P22: =IFERROR(COUNTIFS('Event stream steps'!$C$2:$C$331,$A22,'Event stream steps'!$K$2:$K$331,P$6)/$C22,0) -> 0.6637931 | Q22: =IFERROR(COUNTIFS('Event stream steps'!$C$2:$C$331,$A22,'Event stream steps'!$K$2:$K$331,Q$6)/$C22,0) -> 0.3362069 | R22: =IFERROR(COUNTIFS('Event stream steps'!$C$2:$C$331,$A22,'Event stream steps'!$K$2:$K$331,R$6)/$C22,0) -> 0
A23: Van | B23: Acquisition | C23: =COUNTIFS('Event stream steps'!$C$2:$C$331,$A23,'Event stream steps'!$D$2:$D$331,$B23) -> 19 | D23: =IFERROR(COUNTIFS('Event stream steps'!$C$2:$C$331,$A23,'Event stream steps'!$D$2:$D$331,$B23,'Event stream steps'!$G$2:$G$331,D$6)/$C23,0) -> 1 | E23: =IFERROR(COUNTIFS('Event stream steps'!$C$2:$C$331,$A23,'Event stream steps'!$D$2:$D$331,$B23,'Event stream steps'!$G$2:$G$331,E$6)/$C23,0) -> 0 | F23: =IFERROR(COUNTIFS('Event stream steps'!$C$2:$C$331,$A23,'Event stream steps'!$D$2:$D$331,$B23,'Event stream steps'!$G$2:$G$331,F$6)/$C23,0) -> 0 | G23: =IFERROR(COUNTIFS('Event stream steps'!$C$2:$C$331,$A23,'Event stream steps'!$D$2:$D$331,$B23,'Event stream steps'!$G$2:$G$331,G$6)/$C23,0) -> 0 | H23: =IFERROR(COUNTIFS('Event stream steps'!$C$2:$C$331,$A23,'Event stream steps'!$D$2:$D$331,$B23,'Event stream steps'!$G$2:$G$331,H$6)/$C23,0) -> 0 | I23: =IFERROR(COUNTIFS('Event stream steps'!$C$2:$C$331,$A23,'Event stream steps'!$D$2:$D$331,$B23,'Event stream steps'!$G$2:$G$331,I$6)/$C23,0) -> 0 | J23: =IFERROR(COUNTIFS('Event stream steps'!$C$2:$C$331,$A23,'Event stream steps'!$D$2:$D$331,$B23,'Event stream steps'!$G$2:$G$331,J$6)/$C23,0) -> 0 | K23: =IFERROR(COUNTIFS('Event stream steps'!$C$2:$C$331,$A23,'Event stream steps'!$D$2:$D$331,$B23,'Event stream steps'!$G$2:$G$331,K$6)/$C23,0) -> 0 | M23: =IFERROR(COUNTIFS('Event stream steps'!$C$2:$C$331,$A23,'Event stream steps'!$D$2:$D$331,$B23,'Event stream steps'!$I$2:$I$331,M$6)/$C23,0) -> 0 | N23: =IFERROR(COUNTIFS('Event stream steps'!$C$2:$C$331,$A23,'Event stream steps'!$D$2:$D$331,$B23,'Event stream steps'!$I$2:$I$331,N$6)/$C23,0) -> 1 | P23: =IFERROR(COUNTIFS('Event stream steps'!$C$2:$C$331,$A23,'Event stream steps'!$D$2:$D$331,$B23,'Event stream steps'!$K$2:$K$331,P$6)/$C23,0) -> 0.78947368 | Q23: =IFERROR(COUNTIFS('Event stream steps'!$C$2:$C$331,$A23,'Event stream steps'!$D$2:$D$331,$B23,'Event stream steps'!$K$2:$K$331,Q$6)/$C23,0) -> 0.21052632 | R23: =IFERROR(COUNTIFS('Event stream steps'!$C$2:$C$331,$A23,'Event stream steps'!$D$2:$D$331,$B23,'Event stream steps'!$K$2:$K$331,R$6)/$C23,0) -> 0
A24: Van | B24: Renewal | C24: =COUNTIFS('Event stream steps'!$C$2:$C$331,$A24,'Event stream steps'!$D$2:$D$331,$B24) -> 27 | D24: =IFERROR(COUNTIFS('Event stream steps'!$C$2:$C$331,$A24,'Event stream steps'!$D$2:$D$331,$B24,'Event stream steps'!$G$2:$G$331,D$6)/$C24,0) -> 1 | E24: =IFERROR(COUNTIFS('Event stream steps'!$C$2:$C$331,$A24,'Event stream steps'!$D$2:$D$331,$B24,'Event stream steps'!$G$2:$G$331,E$6)/$C24,0) -> 0 | F24: =IFERROR(COUNTIFS('Event stream steps'!$C$2:$C$331,$A24,'Event stream steps'!$D$2:$D$331,$B24,'Event stream steps'!$G$2:$G$331,F$6)/$C24,0) -> 0 | G24: =IFERROR(COUNTIFS('Event stream steps'!$C$2:$C$331,$A24,'Event stream steps'!$D$2:$D$331,$B24,'Event stream steps'!$G$2:$G$331,G$6)/$C24,0) -> 0 | H24: =IFERROR(COUNTIFS('Event stream steps'!$C$2:$C$331,$A24,'Event stream steps'!$D$2:$D$331,$B24,'Event stream steps'!$G$2:$G$331,H$6)/$C24,0) -> 0 | I24: =IFERROR(COUNTIFS('Event stream steps'!$C$2:$C$331,$A24,'Event stream steps'!$D$2:$D$331,$B24,'Event stream steps'!$G$2:$G$331,I$6)/$C24,0) -> 0 | J24: =IFERROR(COUNTIFS('Event stream steps'!$C$2:$C$331,$A24,'Event stream steps'!$D$2:$D$331,$B24,'Event stream steps'!$G$2:$G$331,J$6)/$C24,0) -> 0 | K24: =IFERROR(COUNTIFS('Event stream steps'!$C$2:$C$331,$A24,'Event stream steps'!$D$2:$D$331,$B24,'Event stream steps'!$G$2:$G$331,K$6)/$C24,0) -> 0 | M24: =IFERROR(COUNTIFS('Event stream steps'!$C$2:$C$331,$A24,'Event stream steps'!$D$2:$D$331,$B24,'Event stream steps'!$I$2:$I$331,M$6)/$C24,0) -> 0 | N24: =IFERROR(COUNTIFS('Event stream steps'!$C$2:$C$331,$A24,'Event stream steps'!$D$2:$D$331,$B24,'Event stream steps'!$I$2:$I$331,N$6)/$C24,0) -> 1 | P24: =IFERROR(COUNTIFS('Event stream steps'!$C$2:$C$331,$A24,'Event stream steps'!$D$2:$D$331,$B24,'Event stream steps'!$K$2:$K$331,P$6)/$C24,0) -> 0.62962963 | Q24: =IFERROR(COUNTIFS('Event stream steps'!$C$2:$C$331,$A24,'Event stream steps'!$D$2:$D$331,$B24,'Event stream steps'!$K$2:$K$331,Q$6)/$C24,0) -> 0.37037037 | R24: =IFERROR(COUNTIFS('Event stream steps'!$C$2:$C$331,$A24,'Event stream steps'!$D$2:$D$331,$B24,'Event stream steps'!$K$2:$K$331,R$6)/$C24,0) -> 0
A25: Van | B25: MTA | C25: =COUNTIFS('Event stream steps'!$C$2:$C$331,$A25,'Event stream steps'!$D$2:$D$331,$B25) -> 16 | D25: =IFERROR(COUNTIFS('Event stream steps'!$C$2:$C$331,$A25,'Event stream steps'!$D$2:$D$331,$B25,'Event stream steps'!$G$2:$G$331,D$6)/$C25,0) -> 1 | E25: =IFERROR(COUNTIFS('Event stream steps'!$C$2:$C$331,$A25,'Event stream steps'!$D$2:$D$331,$B25,'Event stream steps'!$G$2:$G$331,E$6)/$C25,0) -> 0 | F25: =IFERROR(COUNTIFS('Event stream steps'!$C$2:$C$331,$A25,'Event stream steps'!$D$2:$D$331,$B25,'Event stream steps'!$G$2:$G$331,F$6)/$C25,0) -> 0 | G25: =IFERROR(COUNTIFS('Event stream steps'!$C$2:$C$331,$A25,'Event stream steps'!$D$2:$D$331,$B25,'Event stream steps'!$G$2:$G$331,G$6)/$C25,0) -> 0 | H25: =IFERROR(COUNTIFS('Event stream steps'!$C$2:$C$331,$A25,'Event stream steps'!$D$2:$D$331,$B25,'Event stream steps'!$G$2:$G$331,H$6)/$C25,0) -> 0 | I25: =IFERROR(COUNTIFS('Event stream steps'!$C$2:$C$331,$A25,'Event stream steps'!$D$2:$D$331,$B25,'Event stream steps'!$G$2:$G$331,I$6)/$C25,0) -> 0 | J25: =IFERROR(COUNTIFS('Event stream steps'!$C$2:$C$331,$A25,'Event stream steps'!$D$2:$D$331,$B25,'Event stream steps'!$G$2:$G$331,J$6)/$C25,0) -> 0 | K25: =IFERROR(COUNTIFS('Event stream steps'!$C$2:$C$331,$A25,'Event stream steps'!$D$2:$D$331,$B25,'Event stream steps'!$G$2:$G$331,K$6)/$C25,0) -> 0 | M25: =IFERROR(COUNTIFS('Event stream steps'!$C$2:$C$331,$A25,'Event stream steps'!$D$2:$D$331,$B25,'Event stream steps'!$I$2:$I$331,M$6)/$C25,0) -> 0 | N25: =IFERROR(COUNTIFS('Event stream steps'!$C$2:$C$331,$A25,'Event stream steps'!$D$2:$D$331,$B25,'Event stream steps'!$I$2:$I$331,N$6)/$C25,0) -> 1 | P25: =IFERROR(COUNTIFS('Event stream steps'!$C$2:$C$331,$A25,'Event stream steps'!$D$2:$D$331,$B25,'Event stream steps'!$K$2:$K$331,P$6)/$C25,0) -> 0.6875 | Q25: =IFERROR(COUNTIFS('Event stream steps'!$C$2:$C$331,$A25,'Event stream steps'!$D$2:$D$331,$B25,'Event stream steps'!$K$2:$K$331,Q$6)/$C25,0) -> 0.3125 | R25: =IFERROR(COUNTIFS('Event stream steps'!$C$2:$C$331,$A25,'Event stream steps'!$D$2:$D$331,$B25,'Event stream steps'!$K$2:$K$331,R$6)/$C25,0) -> 0
A26: Van | B26: Cancellation | C26: =COUNTIFS('Event stream steps'!$C$2:$C$331,$A26,'Event stream steps'!$D$2:$D$331,$B26) -> 6 | D26: =IFERROR(COUNTIFS('Event stream steps'!$C$2:$C$331,$A26,'Event stream steps'!$D$2:$D$331,$B26,'Event stream steps'!$G$2:$G$331,D$6)/$C26,0) -> 1 | E26: =IFERROR(COUNTIFS('Event stream steps'!$C$2:$C$331,$A26,'Event stream steps'!$D$2:$D$331,$B26,'Event stream steps'!$G$2:$G$331,E$6)/$C26,0) -> 0 | F26: =IFERROR(COUNTIFS('Event stream steps'!$C$2:$C$331,$A26,'Event stream steps'!$D$2:$D$331,$B26,'Event stream steps'!$G$2:$G$331,F$6)/$C26,0) -> 0 | G26: =IFERROR(COUNTIFS('Event stream steps'!$C$2:$C$331,$A26,'Event stream steps'!$D$2:$D$331,$B26,'Event stream steps'!$G$2:$G$331,G$6)/$C26,0) -> 0 | H26: =IFERROR(COUNTIFS('Event stream steps'!$C$2:$C$331,$A26,'Event stream steps'!$D$2:$D$331,$B26,'Event stream steps'!$G$2:$G$331,H$6)/$C26,0) -> 0 | I26: =IFERROR(COUNTIFS('Event stream steps'!$C$2:$C$331,$A26,'Event stream steps'!$D$2:$D$331,$B26,'Event stream steps'!$G$2:$G$331,I$6)/$C26,0) -> 0 | J26: =IFERROR(COUNTIFS('Event stream steps'!$C$2:$C$331,$A26,'Event stream steps'!$D$2:$D$331,$B26,'Event stream steps'!$G$2:$G$331,J$6)/$C26,0) -> 0 | K26: =IFERROR(COUNTIFS('Event stream steps'!$C$2:$C$331,$A26,'Event stream steps'!$D$2:$D$331,$B26,'Event stream steps'!$G$2:$G$331,K$6)/$C26,0) -> 0 | M26: =IFERROR(COUNTIFS('Event stream steps'!$C$2:$C$331,$A26,'Event stream steps'!$D$2:$D$331,$B26,'Event stream steps'!$I$2:$I$331,M$6)/$C26,0) -> 0.16666667 | N26: =IFERROR(COUNTIFS('Event stream steps'!$C$2:$C$331,$A26,'Event stream steps'!$D$2:$D$331,$B26,'Event stream steps'!$I$2:$I$331,N$6)/$C26,0) -> 0.83333333 | P26: =IFERROR(COUNTIFS('Event stream steps'!$C$2:$C$331,$A26,'Event stream steps'!$D$2:$D$331,$B26,'Event stream steps'!$K$2:$K$331,P$6)/$C26,0) -> 1 | Q26: =IFERROR(COUNTIFS('Event stream steps'!$C$2:$C$331,$A26,'Event stream steps'!$D$2:$D$331,$B26,'Event stream steps'!$K$2:$K$331,Q$6)/$C26,0) -> 0 | R26: =IFERROR(COUNTIFS('Event stream steps'!$C$2:$C$331,$A26,'Event stream steps'!$D$2:$D$331,$B26,'Event stream steps'!$K$2:$K$331,R$6)/$C26,0) -> 0
A27: Van | B27: Arrears | C27: =COUNTIFS('Event stream steps'!$C$2:$C$331,$A27,'Event stream steps'!$D$2:$D$331,$B27) -> 6 | D27: =IFERROR(COUNTIFS('Event stream steps'!$C$2:$C$331,$A27,'Event stream steps'!$D$2:$D$331,$B27,'Event stream steps'!$G$2:$G$331,D$6)/$C27,0) -> 1 | E27: =IFERROR(COUNTIFS('Event stream steps'!$C$2:$C$331,$A27,'Event stream steps'!$D$2:$D$331,$B27,'Event stream steps'!$G$2:$G$331,E$6)/$C27,0) -> 0 | F27: =IFERROR(COUNTIFS('Event stream steps'!$C$2:$C$331,$A27,'Event stream steps'!$D$2:$D$331,$B27,'Event stream steps'!$G$2:$G$331,F$6)/$C27,0) -> 0 | G27: =IFERROR(COUNTIFS('Event stream steps'!$C$2:$C$331,$A27,'Event stream steps'!$D$2:$D$331,$B27,'Event stream steps'!$G$2:$G$331,G$6)/$C27,0) -> 0 | H27: =IFERROR(COUNTIFS('Event stream steps'!$C$2:$C$331,$A27,'Event stream steps'!$D$2:$D$331,$B27,'Event stream steps'!$G$2:$G$331,H$6)/$C27,0) -> 0 | I27: =IFERROR(COUNTIFS('Event stream steps'!$C$2:$C$331,$A27,'Event stream steps'!$D$2:$D$331,$B27,'Event stream steps'!$G$2:$G$331,I$6)/$C27,0) -> 0 | J27: =IFERROR(COUNTIFS('Event stream steps'!$C$2:$C$331,$A27,'Event stream steps'!$D$2:$D$331,$B27,'Event stream steps'!$G$2:$G$331,J$6)/$C27,0) -> 0 | K27: =IFERROR(COUNTIFS('Event stream steps'!$C$2:$C$331,$A27,'Event stream steps'!$D$2:$D$331,$B27,'Event stream steps'!$G$2:$G$331,K$6)/$C27,0) -> 0 | M27: =IFERROR(COUNTIFS('Event stream steps'!$C$2:$C$331,$A27,'Event stream steps'!$D$2:$D$331,$B27,'Event stream steps'!$I$2:$I$331,M$6)/$C27,0) -> 0 | N27: =IFERROR(COUNTIFS('Event stream steps'!$C$2:$C$331,$A27,'Event stream steps'!$D$2:$D$331,$B27,'Event stream steps'!$I$2:$I$331,N$6)/$C27,0) -> 1 | P27: =IFERROR(COUNTIFS('Event stream steps'!$C$2:$C$331,$A27,'Event stream steps'!$D$2:$D$331,$B27,'Event stream steps'!$K$2:$K$331,P$6)/$C27,0) -> 1 | Q27: =IFERROR(COUNTIFS('Event stream steps'!$C$2:$C$331,$A27,'Event stream steps'!$D$2:$D$331,$B27,'Event stream steps'!$K$2:$K$331,Q$6)/$C27,0) -> 0 | R27: =IFERROR(COUNTIFS('Event stream steps'!$C$2:$C$331,$A27,'Event stream steps'!$D$2:$D$331,$B27,'Event stream steps'!$K$2:$K$331,R$6)/$C27,0) -> 0
A28: Van | B28: Claims | C28: =COUNTIFS('Event stream steps'!$C$2:$C$331,$A28,'Event stream steps'!$D$2:$D$331,$B28) -> 1 | D28: =IFERROR(COUNTIFS('Event stream steps'!$C$2:$C$331,$A28,'Event stream steps'!$D$2:$D$331,$B28,'Event stream steps'!$G$2:$G$331,D$6)/$C28,0) -> 1 | E28: =IFERROR(COUNTIFS('Event stream steps'!$C$2:$C$331,$A28,'Event stream steps'!$D$2:$D$331,$B28,'Event stream steps'!$G$2:$G$331,E$6)/$C28,0) -> 0 | F28: =IFERROR(COUNTIFS('Event stream steps'!$C$2:$C$331,$A28,'Event stream steps'!$D$2:$D$331,$B28,'Event stream steps'!$G$2:$G$331,F$6)/$C28,0) -> 0 | G28: =IFERROR(COUNTIFS('Event stream steps'!$C$2:$C$331,$A28,'Event stream steps'!$D$2:$D$331,$B28,'Event stream steps'!$G$2:$G$331,G$6)/$C28,0) -> 0 | H28: =IFERROR(COUNTIFS('Event stream steps'!$C$2:$C$331,$A28,'Event stream steps'!$D$2:$D$331,$B28,'Event stream steps'!$G$2:$G$331,H$6)/$C28,0) -> 0 | I28: =IFERROR(COUNTIFS('Event stream steps'!$C$2:$C$331,$A28,'Event stream steps'!$D$2:$D$331,$B28,'Event stream steps'!$G$2:$G$331,I$6)/$C28,0) -> 0 | J28: =IFERROR(COUNTIFS('Event stream steps'!$C$2:$C$331,$A28,'Event stream steps'!$D$2:$D$331,$B28,'Event stream steps'!$G$2:$G$331,J$6)/$C28,0) -> 0 | K28: =IFERROR(COUNTIFS('Event stream steps'!$C$2:$C$331,$A28,'Event stream steps'!$D$2:$D$331,$B28,'Event stream steps'!$G$2:$G$331,K$6)/$C28,0) -> 0 | M28: =IFERROR(COUNTIFS('Event stream steps'!$C$2:$C$331,$A28,'Event stream steps'!$D$2:$D$331,$B28,'Event stream steps'!$I$2:$I$331,M$6)/$C28,0) -> 0 | N28: =IFERROR(COUNTIFS('Event stream steps'!$C$2:$C$331,$A28,'Event stream steps'!$D$2:$D$331,$B28,'Event stream steps'!$I$2:$I$331,N$6)/$C28,0) -> 1 | P28: =IFERROR(COUNTIFS('Event stream steps'!$C$2:$C$331,$A28,'Event stream steps'!$D$2:$D$331,$B28,'Event stream steps'!$K$2:$K$331,P$6)/$C28,0) -> 0 | Q28: =IFERROR(COUNTIFS('Event stream steps'!$C$2:$C$331,$A28,'Event stream steps'!$D$2:$D$331,$B28,'Event stream steps'!$K$2:$K$331,Q$6)/$C28,0) -> 1 | R28: =IFERROR(COUNTIFS('Event stream steps'!$C$2:$C$331,$A28,'Event stream steps'!$D$2:$D$331,$B28,'Event stream steps'!$K$2:$K$331,R$6)/$C28,0) -> 0
A29: Van | B29: Doc Request | C29: =COUNTIFS('Event stream steps'!$C$2:$C$331,$A29,'Event stream steps'!$D$2:$D$331,$B29) -> 6 | D29: =IFERROR(COUNTIFS('Event stream steps'!$C$2:$C$331,$A29,'Event stream steps'!$D$2:$D$331,$B29,'Event stream steps'!$G$2:$G$331,D$6)/$C29,0) -> 1 | E29: =IFERROR(COUNTIFS('Event stream steps'!$C$2:$C$331,$A29,'Event stream steps'!$D$2:$D$331,$B29,'Event stream steps'!$G$2:$G$331,E$6)/$C29,0) -> 0 | F29: =IFERROR(COUNTIFS('Event stream steps'!$C$2:$C$331,$A29,'Event stream steps'!$D$2:$D$331,$B29,'Event stream steps'!$G$2:$G$331,F$6)/$C29,0) -> 0 | G29: =IFERROR(COUNTIFS('Event stream steps'!$C$2:$C$331,$A29,'Event stream steps'!$D$2:$D$331,$B29,'Event stream steps'!$G$2:$G$331,G$6)/$C29,0) -> 0 | H29: =IFERROR(COUNTIFS('Event stream steps'!$C$2:$C$331,$A29,'Event stream steps'!$D$2:$D$331,$B29,'Event stream steps'!$G$2:$G$331,H$6)/$C29,0) -> 0 | I29: =IFERROR(COUNTIFS('Event stream steps'!$C$2:$C$331,$A29,'Event stream steps'!$D$2:$D$331,$B29,'Event stream steps'!$G$2:$G$331,I$6)/$C29,0) -> 0 | J29: =IFERROR(COUNTIFS('Event stream steps'!$C$2:$C$331,$A29,'Event stream steps'!$D$2:$D$331,$B29,'Event stream steps'!$G$2:$G$331,J$6)/$C29,0) -> 0 | K29: =IFERROR(COUNTIFS('Event stream steps'!$C$2:$C$331,$A29,'Event stream steps'!$D$2:$D$331,$B29,'Event stream steps'!$G$2:$G$331,K$6)/$C29,0) -> 0 | M29: =IFERROR(COUNTIFS('Event stream steps'!$C$2:$C$331,$A29,'Event stream steps'!$D$2:$D$331,$B29,'Event stream steps'!$I$2:$I$331,M$6)/$C29,0) -> 0 | N29: =IFERROR(COUNTIFS('Event stream steps'!$C$2:$C$331,$A29,'Event stream steps'!$D$2:$D$331,$B29,'Event stream steps'!$I$2:$I$331,N$6)/$C29,0) -> 1 | P29: =IFERROR(COUNTIFS('Event stream steps'!$C$2:$C$331,$A29,'Event stream steps'!$D$2:$D$331,$B29,'Event stream steps'!$K$2:$K$331,P$6)/$C29,0) -> 0 | Q29: =IFERROR(COUNTIFS('Event stream steps'!$C$2:$C$331,$A29,'Event stream steps'!$D$2:$D$331,$B29,'Event stream steps'!$K$2:$K$331,Q$6)/$C29,0) -> 1 | R29: =IFERROR(COUNTIFS('Event stream steps'!$C$2:$C$331,$A29,'Event stream steps'!$D$2:$D$331,$B29,'Event stream steps'!$K$2:$K$331,R$6)/$C29,0) -> 0
A30: Van | B30: All episodes | C30: =COUNTIFS('Event stream steps'!$C$2:$C$331,$A30) -> 81 | D30: =IFERROR(COUNTIFS('Event stream steps'!$C$2:$C$331,$A30,'Event stream steps'!$G$2:$G$331,D$6)/$C30,0) -> 1 | E30: =IFERROR(COUNTIFS('Event stream steps'!$C$2:$C$331,$A30,'Event stream steps'!$G$2:$G$331,E$6)/$C30,0) -> 0 | F30: =IFERROR(COUNTIFS('Event stream steps'!$C$2:$C$331,$A30,'Event stream steps'!$G$2:$G$331,F$6)/$C30,0) -> 0 | G30: =IFERROR(COUNTIFS('Event stream steps'!$C$2:$C$331,$A30,'Event stream steps'!$G$2:$G$331,G$6)/$C30,0) -> 0 | H30: =IFERROR(COUNTIFS('Event stream steps'!$C$2:$C$331,$A30,'Event stream steps'!$G$2:$G$331,H$6)/$C30,0) -> 0 | I30: =IFERROR(COUNTIFS('Event stream steps'!$C$2:$C$331,$A30,'Event stream steps'!$G$2:$G$331,I$6)/$C30,0) -> 0 | J30: =IFERROR(COUNTIFS('Event stream steps'!$C$2:$C$331,$A30,'Event stream steps'!$G$2:$G$331,J$6)/$C30,0) -> 0 | K30: =IFERROR(COUNTIFS('Event stream steps'!$C$2:$C$331,$A30,'Event stream steps'!$G$2:$G$331,K$6)/$C30,0) -> 0 | M30: =IFERROR(COUNTIFS('Event stream steps'!$C$2:$C$331,$A30,'Event stream steps'!$I$2:$I$331,M$6)/$C30,0) -> 0.012345679 | N30: =IFERROR(COUNTIFS('Event stream steps'!$C$2:$C$331,$A30,'Event stream steps'!$I$2:$I$331,N$6)/$C30,0) -> 0.98765432 | P30: =IFERROR(COUNTIFS('Event stream steps'!$C$2:$C$331,$A30,'Event stream steps'!$K$2:$K$331,P$6)/$C30,0) -> 0.67901235 | Q30: =IFERROR(COUNTIFS('Event stream steps'!$C$2:$C$331,$A30,'Event stream steps'!$K$2:$K$331,Q$6)/$C30,0) -> 0.32098765 | R30: =IFERROR(COUNTIFS('Event stream steps'!$C$2:$C$331,$A30,'Event stream steps'!$K$2:$K$331,R$6)/$C30,0) -> 0
A31: Travel | B31: Acquisition | C31: =COUNTIFS('Event stream steps'!$C$2:$C$331,$A31,'Event stream steps'!$D$2:$D$331,$B31) -> 4 | D31: =IFERROR(COUNTIFS('Event stream steps'!$C$2:$C$331,$A31,'Event stream steps'!$D$2:$D$331,$B31,'Event stream steps'!$G$2:$G$331,D$6)/$C31,0) -> 1 | E31: =IFERROR(COUNTIFS('Event stream steps'!$C$2:$C$331,$A31,'Event stream steps'!$D$2:$D$331,$B31,'Event stream steps'!$G$2:$G$331,E$6)/$C31,0) -> 0 | F31: =IFERROR(COUNTIFS('Event stream steps'!$C$2:$C$331,$A31,'Event stream steps'!$D$2:$D$331,$B31,'Event stream steps'!$G$2:$G$331,F$6)/$C31,0) -> 0 | G31: =IFERROR(COUNTIFS('Event stream steps'!$C$2:$C$331,$A31,'Event stream steps'!$D$2:$D$331,$B31,'Event stream steps'!$G$2:$G$331,G$6)/$C31,0) -> 0 | H31: =IFERROR(COUNTIFS('Event stream steps'!$C$2:$C$331,$A31,'Event stream steps'!$D$2:$D$331,$B31,'Event stream steps'!$G$2:$G$331,H$6)/$C31,0) -> 0 | I31: =IFERROR(COUNTIFS('Event stream steps'!$C$2:$C$331,$A31,'Event stream steps'!$D$2:$D$331,$B31,'Event stream steps'!$G$2:$G$331,I$6)/$C31,0) -> 0 | J31: =IFERROR(COUNTIFS('Event stream steps'!$C$2:$C$331,$A31,'Event stream steps'!$D$2:$D$331,$B31,'Event stream steps'!$G$2:$G$331,J$6)/$C31,0) -> 0 | K31: =IFERROR(COUNTIFS('Event stream steps'!$C$2:$C$331,$A31,'Event stream steps'!$D$2:$D$331,$B31,'Event stream steps'!$G$2:$G$331,K$6)/$C31,0) -> 0 | M31: =IFERROR(COUNTIFS('Event stream steps'!$C$2:$C$331,$A31,'Event stream steps'!$D$2:$D$331,$B31,'Event stream steps'!$I$2:$I$331,M$6)/$C31,0) -> 0 | N31: =IFERROR(COUNTIFS('Event stream steps'!$C$2:$C$331,$A31,'Event stream steps'!$D$2:$D$331,$B31,'Event stream steps'!$I$2:$I$331,N$6)/$C31,0) -> 1 | P31: =IFERROR(COUNTIFS('Event stream steps'!$C$2:$C$331,$A31,'Event stream steps'!$D$2:$D$331,$B31,'Event stream steps'!$K$2:$K$331,P$6)/$C31,0) -> 0.75 | Q31: =IFERROR(COUNTIFS('Event stream steps'!$C$2:$C$331,$A31,'Event stream steps'!$D$2:$D$331,$B31,'Event stream steps'!$K$2:$K$331,Q$6)/$C31,0) -> 0.25 | R31: =IFERROR(COUNTIFS('Event stream steps'!$C$2:$C$331,$A31,'Event stream steps'!$D$2:$D$331,$B31,'Event stream steps'!$K$2:$K$331,R$6)/$C31,0) -> 0
A32: Travel | B32: Renewal | C32: =COUNTIFS('Event stream steps'!$C$2:$C$331,$A32,'Event stream steps'!$D$2:$D$331,$B32) -> 3 | D32: =IFERROR(COUNTIFS('Event stream steps'!$C$2:$C$331,$A32,'Event stream steps'!$D$2:$D$331,$B32,'Event stream steps'!$G$2:$G$331,D$6)/$C32,0) -> 1 | E32: =IFERROR(COUNTIFS('Event stream steps'!$C$2:$C$331,$A32,'Event stream steps'!$D$2:$D$331,$B32,'Event stream steps'!$G$2:$G$331,E$6)/$C32,0) -> 0 | F32: =IFERROR(COUNTIFS('Event stream steps'!$C$2:$C$331,$A32,'Event stream steps'!$D$2:$D$331,$B32,'Event stream steps'!$G$2:$G$331,F$6)/$C32,0) -> 0 | G32: =IFERROR(COUNTIFS('Event stream steps'!$C$2:$C$331,$A32,'Event stream steps'!$D$2:$D$331,$B32,'Event stream steps'!$G$2:$G$331,G$6)/$C32,0) -> 0 | H32: =IFERROR(COUNTIFS('Event stream steps'!$C$2:$C$331,$A32,'Event stream steps'!$D$2:$D$331,$B32,'Event stream steps'!$G$2:$G$331,H$6)/$C32,0) -> 0 | I32: =IFERROR(COUNTIFS('Event stream steps'!$C$2:$C$331,$A32,'Event stream steps'!$D$2:$D$331,$B32,'Event stream steps'!$G$2:$G$331,I$6)/$C32,0) -> 0 | J32: =IFERROR(COUNTIFS('Event stream steps'!$C$2:$C$331,$A32,'Event stream steps'!$D$2:$D$331,$B32,'Event stream steps'!$G$2:$G$331,J$6)/$C32,0) -> 0 | K32: =IFERROR(COUNTIFS('Event stream steps'!$C$2:$C$331,$A32,'Event stream steps'!$D$2:$D$331,$B32,'Event stream steps'!$G$2:$G$331,K$6)/$C32,0) -> 0 | M32: =IFERROR(COUNTIFS('Event stream steps'!$C$2:$C$331,$A32,'Event stream steps'!$D$2:$D$331,$B32,'Event stream steps'!$I$2:$I$331,M$6)/$C32,0) -> 0 | N32: =IFERROR(COUNTIFS('Event stream steps'!$C$2:$C$331,$A32,'Event stream steps'!$D$2:$D$331,$B32,'Event stream steps'!$I$2:$I$331,N$6)/$C32,0) -> 1 | P32: =IFERROR(COUNTIFS('Event stream steps'!$C$2:$C$331,$A32,'Event stream steps'!$D$2:$D$331,$B32,'Event stream steps'!$K$2:$K$331,P$6)/$C32,0) -> 1 | Q32: =IFERROR(COUNTIFS('Event stream steps'!$C$2:$C$331,$A32,'Event stream steps'!$D$2:$D$331,$B32,'Event stream steps'!$K$2:$K$331,Q$6)/$C32,0) -> 0 | R32: =IFERROR(COUNTIFS('Event stream steps'!$C$2:$C$331,$A32,'Event stream steps'!$D$2:$D$331,$B32,'Event stream steps'!$K$2:$K$331,R$6)/$C32,0) -> 0
A33: Travel | B33: All episodes | C33: =COUNTIFS('Event stream steps'!$C$2:$C$331,$A33) -> 7 | D33: =IFERROR(COUNTIFS('Event stream steps'!$C$2:$C$331,$A33,'Event stream steps'!$G$2:$G$331,D$6)/$C33,0) -> 1 | E33: =IFERROR(COUNTIFS('Event stream steps'!$C$2:$C$331,$A33,'Event stream steps'!$G$2:$G$331,E$6)/$C33,0) -> 0 | F33: =IFERROR(COUNTIFS('Event stream steps'!$C$2:$C$331,$A33,'Event stream steps'!$G$2:$G$331,F$6)/$C33,0) -> 0 | G33: =IFERROR(COUNTIFS('Event stream steps'!$C$2:$C$331,$A33,'Event stream steps'!$G$2:$G$331,G$6)/$C33,0) -> 0 | H33: =IFERROR(COUNTIFS('Event stream steps'!$C$2:$C$331,$A33,'Event stream steps'!$G$2:$G$331,H$6)/$C33,0) -> 0 | I33: =IFERROR(COUNTIFS('Event stream steps'!$C$2:$C$331,$A33,'Event stream steps'!$G$2:$G$331,I$6)/$C33,0) -> 0 | J33: =IFERROR(COUNTIFS('Event stream steps'!$C$2:$C$331,$A33,'Event stream steps'!$G$2:$G$331,J$6)/$C33,0) -> 0 | K33: =IFERROR(COUNTIFS('Event stream steps'!$C$2:$C$331,$A33,'Event stream steps'!$G$2:$G$331,K$6)/$C33,0) -> 0 | M33: =IFERROR(COUNTIFS('Event stream steps'!$C$2:$C$331,$A33,'Event stream steps'!$I$2:$I$331,M$6)/$C33,0) -> 0 | N33: =IFERROR(COUNTIFS('Event stream steps'!$C$2:$C$331,$A33,'Event stream steps'!$I$2:$I$331,N$6)/$C33,0) -> 1 | P33: =IFERROR(COUNTIFS('Event stream steps'!$C$2:$C$331,$A33,'Event stream steps'!$K$2:$K$331,P$6)/$C33,0) -> 0.85714286 | Q33: =IFERROR(COUNTIFS('Event stream steps'!$C$2:$C$331,$A33,'Event stream steps'!$K$2:$K$331,Q$6)/$C33,0) -> 0.14285714 | R33: =IFERROR(COUNTIFS('Event stream steps'!$C$2:$C$331,$A33,'Event stream steps'!$K$2:$K$331,R$6)/$C33,0) -> 0
A34: All products | B34: All episodes | C34: =COUNTA('Event stream steps'!$A$2:$A$331) -> 330 | D34: =IFERROR(COUNTIFS('Event stream steps'!$G$2:$G$331,D$6)/$C34,0) -> 1 | E34: =IFERROR(COUNTIFS('Event stream steps'!$G$2:$G$331,E$6)/$C34,0) -> 0 | F34: =IFERROR(COUNTIFS('Event stream steps'!$G$2:$G$331,F$6)/$C34,0) -> 0 | G34: =IFERROR(COUNTIFS('Event stream steps'!$G$2:$G$331,G$6)/$C34,0) -> 0 | H34: =IFERROR(COUNTIFS('Event stream steps'!$G$2:$G$331,H$6)/$C34,0) -> 0 | I34: =IFERROR(COUNTIFS('Event stream steps'!$G$2:$G$331,I$6)/$C34,0) -> 0 | J34: =IFERROR(COUNTIFS('Event stream steps'!$G$2:$G$331,J$6)/$C34,0) -> 0 | K34: =IFERROR(COUNTIFS('Event stream steps'!$G$2:$G$331,K$6)/$C34,0) -> 0 | M34: =IFERROR(COUNTIFS('Event stream steps'!$I$2:$I$331,M$6)/$C34,0) -> 0.015151515 | N34: =IFERROR(COUNTIFS('Event stream steps'!$I$2:$I$331,N$6)/$C34,0) -> 0.98484848 | P34: =IFERROR(COUNTIFS('Event stream steps'!$K$2:$K$331,P$6)/$C34,0) -> 0.64242424 | Q34: =IFERROR(COUNTIFS('Event stream steps'!$K$2:$K$331,Q$6)/$C34,0) -> 0.35757576 | R34: =IFERROR(COUNTIFS('Event stream steps'!$K$2:$K$331,R$6)/$C34,0) -> 0
A36: Percentages on each row add to 100%. Steps counts change only if rows are added to or removed from the Event stream steps tab.

Sheet Source migration
A1: Source tables to migrate
A2: Every table script 04 reads that is not already in ods, grouped by schema. Steps affected counts how many of the 330 event steps depend on the table, following the staging tables the script builds itself, so a table read only by a staging build still shows the steps behind it. The tables script 04 builds are listed too: each one is a decision about whether it becomes an ods object or disappears once its own sources move.
A5: Schema | B5: Tables | C5: Needs triage | D5: Triaged | E5: Already available in ods | F5: Blocked | G5: In progress | H5: Migrated | I5: Not required
A6: edw | B6: =COUNTIF($A$14:$A$55,$A6) -> 9 | C6: =COUNTIFS($A$14:$A$55,$A6,$G$14:$G$55,C$5) -> 9 | D6: =COUNTIFS($A$14:$A$55,$A6,$G$14:$G$55,D$5) -> 0 | E6: =COUNTIFS($A$14:$A$55,$A6,$G$14:$G$55,E$5) -> 0 | F6: =COUNTIFS($A$14:$A$55,$A6,$G$14:$G$55,F$5) -> 0 | G6: =COUNTIFS($A$14:$A$55,$A6,$G$14:$G$55,G$5) -> 0 | H6: =COUNTIFS($A$14:$A$55,$A6,$G$14:$G$55,H$5) -> 0 | I6: =COUNTIFS($A$14:$A$55,$A6,$G$14:$G$55,I$5) -> 0
A7: dlk | B7: =COUNTIF($A$14:$A$55,$A7) -> 26 | C7: =COUNTIFS($A$14:$A$55,$A7,$G$14:$G$55,C$5) -> 26 | D7: =COUNTIFS($A$14:$A$55,$A7,$G$14:$G$55,D$5) -> 0 | E7: =COUNTIFS($A$14:$A$55,$A7,$G$14:$G$55,E$5) -> 0 | F7: =COUNTIFS($A$14:$A$55,$A7,$G$14:$G$55,F$5) -> 0 | G7: =COUNTIFS($A$14:$A$55,$A7,$G$14:$G$55,G$5) -> 0 | H7: =COUNTIFS($A$14:$A$55,$A7,$G$14:$G$55,H$5) -> 0 | I7: =COUNTIFS($A$14:$A$55,$A7,$G$14:$G$55,I$5) -> 0
A8: pii | B8: =COUNTIF($A$14:$A$55,$A8) -> 1 | C8: =COUNTIFS($A$14:$A$55,$A8,$G$14:$G$55,C$5) -> 1 | D8: =COUNTIFS($A$14:$A$55,$A8,$G$14:$G$55,D$5) -> 0 | E8: =COUNTIFS($A$14:$A$55,$A8,$G$14:$G$55,E$5) -> 0 | F8: =COUNTIFS($A$14:$A$55,$A8,$G$14:$G$55,F$5) -> 0 | G8: =COUNTIFS($A$14:$A$55,$A8,$G$14:$G$55,G$5) -> 0 | H8: =COUNTIFS($A$14:$A$55,$A8,$G$14:$G$55,H$5) -> 0 | I8: =COUNTIFS($A$14:$A$55,$A8,$G$14:$G$55,I$5) -> 0
A9: tmp | B9: =COUNTIF($A$14:$A$55,$A9) -> 1 | C9: =COUNTIFS($A$14:$A$55,$A9,$G$14:$G$55,C$5) -> 1 | D9: =COUNTIFS($A$14:$A$55,$A9,$G$14:$G$55,D$5) -> 0 | E9: =COUNTIFS($A$14:$A$55,$A9,$G$14:$G$55,E$5) -> 0 | F9: =COUNTIFS($A$14:$A$55,$A9,$G$14:$G$55,F$5) -> 0 | G9: =COUNTIFS($A$14:$A$55,$A9,$G$14:$G$55,G$5) -> 0 | H9: =COUNTIFS($A$14:$A$55,$A9,$G$14:$G$55,H$5) -> 0 | I9: =COUNTIFS($A$14:$A$55,$A9,$G$14:$G$55,I$5) -> 0
A10: stg | B10: =COUNTIF($A$14:$A$55,$A10) -> 5 | C10: =COUNTIFS($A$14:$A$55,$A10,$G$14:$G$55,C$5) -> 5 | D10: =COUNTIFS($A$14:$A$55,$A10,$G$14:$G$55,D$5) -> 0 | E10: =COUNTIFS($A$14:$A$55,$A10,$G$14:$G$55,E$5) -> 0 | F10: =COUNTIFS($A$14:$A$55,$A10,$G$14:$G$55,F$5) -> 0 | G10: =COUNTIFS($A$14:$A$55,$A10,$G$14:$G$55,G$5) -> 0 | H10: =COUNTIFS($A$14:$A$55,$A10,$G$14:$G$55,H$5) -> 0 | I10: =COUNTIFS($A$14:$A$55,$A10,$G$14:$G$55,I$5) -> 0
